Workbook

Sheet 售前选配单
A1: 车型售前选配模板
P2: =IF(AND(配置数据库!$C90="售前填写",INDEX(配置数据库!$G90:$AG90,1,MATCH($B$3,配置数据库!$G$8:$AG$8,0))<>""),SUMPRODUCT((配置数据库!$C$90:$C90="售前填写")*(INDEX(配置数据库!$G$90:$AG90,0,MATCH($B$3,配置数据库!$G$8:$AG$8,0))<>"")),"") -> 1 | Q2: =IF(AND(配置数据库!$C90="默认配置",INDEX(配置数据库!$G90:$AG90,1,MATCH($B$3,配置数据库!$G$8:$AG$8,0))<>""),SUMPRODUCT((配置数据库!$C$90:$C90="默认配置")*(INDEX(配置数据库!$G$90:$AG90,0,MATCH($B$3,配置数据库!$G$8:$AG$8,0))<>"")),"")
A3: 车型版本 | B3: Apex 2000-G CE | C3: 项目名称 | P3: =IF(AND(配置数据库!$C10="售前填写",INDEX(配置数据库!$G10:$AG10,1,MATCH($B$3,配置数据库!$G$8:$AG$8,0))<>""),SUMPRODUCT((配置数据库!$C$10:$C10="售前填写")*(INDEX(配置数据库!$G$10:$AG10,0,MATCH($B$3,配置数据库!$G$8:$AG$8,0))<>"")),"") -> 1 | Q3: =IF(AND(配置数据库!$C10="默认配置",INDEX(配置数据库!$G10:$AG10,1,MATCH($B$3,配置数据库!$G$8:$AG$8,0))<>""),SUMPRODUCT((配置数据库!$C$10:$C10="默认配置")*(INDEX(配置数据库!$G$10:$AG10,0,MATCH($B$3,配置数据库!$G$8:$AG$8,0))<>"")),"")
A4: 商机号 | C4: 车型数量 | P4: =IF(AND(配置数据库!#REF!="售前填写",INDEX(配置数据库!#REF!,1,MATCH($B$3,配置数据库!$G$8:$AG$8,0))<>""),SUMPRODUCT((配置数据库!$C$10:$C10="售前填写")*(INDEX(配置数据库!$G$10:$AG10,0,MATCH($B$3,配置数据库!$G$8:$AG$8,0))<>"")),"") -> #REF! | Q4: =IF(AND(配置数据库!#REF!="默认配置",INDEX(配置数据库!#REF!,1,MATCH($B$3,配置数据库!$G$8:$AG$8,0))<>""),SUMPRODUCT((配置数据库!$C$10:$C10="默认配置")*(INDEX(配置数据库!$G$10:$AG10,0,MATCH($B$3,配置数据库!$G$8:$AG$8,0))<>"")),"") -> #REF!
A5: 发货时间 | P5: =IF(AND(配置数据库!#REF!="售前填写",INDEX(配置数据库!#REF!,1,MATCH($B$3,配置数据库!$G$8:$AG$8,0))<>""),SUMPRODUCT((配置数据库!$C$10:$C10="售前填写")*(INDEX(配置数据库!$G$10:$AG10,0,MATCH($B$3,配置数据库!$G$8:$AG$8,0))<>"")),"") -> #REF! | Q5: =IF(AND(配置数据库!#REF!="默认配置",INDEX(配置数据库!#REF!,1,MATCH($B$3,配置数据库!$G$8:$AG$8,0))<>""),SUMPRODUCT((配置数据库!$C$10:$C10="默认配置")*(INDEX(配置数据库!$G$10:$AG10,0,MATCH($B$3,配置数据库!$G$8:$AG$8,0))<>"")),"") -> #REF!
A6: 使用说明 | B6: 配置项、默认值、展示分区和下拉选项均在“配置数据库”维护；黄色单元格为售前可填写/覆盖项。 | P6: =IF(AND(配置数据库!$C11="售前填写",INDEX(配置数据库!$G11:$AG11,1,MATCH($B$3,配置数据库!$G$8:$AG$8,0))<>""),SUMPRODUCT((配置数据库!$C$10:$C11="售前填写")*(INDEX(配置数据库!$G$10:$AG11,0,MATCH($B$3,配置数据库!$G$8:$AG$8,0))<>"")),"") -> 2 | Q6: =IF(AND(配置数据库!$C11="默认配置",INDEX(配置数据库!$G11:$AG11,1,MATCH($B$3,配置数据库!$G$8:$AG$8,0))<>""),SUMPRODUCT((配置数据库!$C$10:$C11="默认配置")*(INDEX(配置数据库!$G$10:$AG11,0,MATCH($B$3,配置数据库!$G$8:$AG$8,0))<>"")),"")
P7: =IF(AND(配置数据库!$C12="售前填写",INDEX(配置数据库!$G12:$AG12,1,MATCH($B$3,配置数据库!$G$8:$AG$8,0))<>""),SUMPRODUCT((配置数据库!$C$10:$C12="售前填写")*(INDEX(配置数据库!$G$10:$AG12,0,MATCH($B$3,配置数据库!$G$8:$AG$8,0))<>"")),"") -> 3 | Q7: =IF(AND(配置数据库!$C12="默认配置",INDEX(配置数据库!$G12:$AG12,1,MATCH($B$3,配置数据库!$G$8:$AG$8,0))<>""),SUMPRODUCT((配置数据库!$C$10:$C12="默认配置")*(INDEX(配置数据库!$G$10:$AG12,0,MATCH($B$3,配置数据库!$G$8:$AG$8,0))<>"")),"")
A8: 配置项 | B8: 配置/需求 | C8: 属性 | D8: 备注 | P8: =IF(AND(配置数据库!$C13="售前填写",INDEX(配置数据库!$G13:$AG13,1,MATCH($B$3,配置数据库!$G$8:$AG$8,0))<>""),SUMPRODUCT((配置数据库!$C$10:$C13="售前填写")*(INDEX(配置数据库!$G$10:$AG13,0,MATCH($B$3,配置数据库!$G$8:$AG$8,0))<>"")),"") | Q8: =IF(AND(配置数据库!$C13="默认配置",INDEX(配置数据库!$G13:$AG13,1,MATCH($B$3,配置数据库!$G$8:$AG$8,0))<>""),SUMPRODUCT((配置数据库!$C$10:$C13="默认配置")*(INDEX(配置数据库!$G$10:$AG13,0,MATCH($B$3,配置数据库!$G$8:$AG$8,0))<>"")),"")
A9: 售前填写区 | P9: =IF(AND(配置数据库!$C15="售前填写",INDEX(配置数据库!$G15:$AG15,1,MATCH($B$3,配置数据库!$G$8:$AG$8,0))<>""),SUMPRODUCT((配置数据库!$C$10:$C15="售前填写")*(INDEX(配置数据库!$G$10:$AG15,0,MATCH($B$3,配置数据库!$G$8:$AG$8,0))<>"")),"") | Q9: =IF(AND(配置数据库!$C15="默认配置",INDEX(配置数据库!$G15:$AG15,1,MATCH($B$3,配置数据库!$G$8:$AG$8,0))<>""),SUMPRODUCT((配置数据库!$C$10:$C15="默认配置")*(INDEX(配置数据库!$G$10:$AG15,0,MATCH($B$3,配置数据库!$G$8:$AG$8,0))<>"")),"")
A10: =IFERROR(INDEX(配置数据库!$A:$A,MATCH(1,$P:$P,0)),"") -> 项目名称 | B10: =IF($A10="","",IFERROR(LEFT(SUBSTITUTE(IFERROR(INDEX(配置数据库!$G:$AG,MATCH(1,$P:$P,0),MATCH($B$3,配置数据库!$G$8:$AG$8,0)),""),";","；"),FIND("；",SUBSTITUTE(IFERROR(INDEX(配置数据库!$G:$AG,MATCH(1,$P:$P,0),MATCH($B$3,配置数据库!$G$8:$AG$8,0)),""),";","；"))-1),IFERROR(INDEX(配置数据库!$G:$AG,MATCH(1,$P:$P,0),MATCH($B$3,配置数据库!$G$8:$AG$8,0)),""))) -> 0 | C10: =IF($A10="","","售前填写") -> 售前填写 | D10: =IF($A10="","",IFERROR(INDEX(配置数据库!$B:$B,MATCH(1,$P:$P,0)),"")) -> 0 | E10: =IF($A10="","",IFERROR(INDEX(配置数据库!$G:$AG,MATCH($A10,配置数据库!$A:$A,0),MATCH($B$3,配置数据库!$G$8:$AG$8,0)),"")) -> 0 | F10: =IF(ISNUMBER(SEARCH("；",SUBSTITUTE($E10,";","；"))),TRIM(MID(SUBSTITUTE(SUBSTITUTE($E10,";","；"),"；",REPT(" ",100)),1,100)),"") | G10: =IF(ISNUMBER(SEARCH("；",SUBSTITUTE($E10,";","；"))),TRIM(MID(SUBSTITUTE(SUBSTITUTE($E10,";","；"),"；",REPT(" ",100)),101,100)),"") | H10: =IF(ISNUMBER(SEARCH("；",SUBSTITUTE($E10,";","；"))),TRIM(MID(SUBSTITUTE(SUBSTITUTE($E10,";","；"),"；",REPT(" ",100)),201,100)),"") | I10: =IF(ISNUMBER(SEARCH("；",SUBSTITUTE($E10,";","；"))),TRIM(MID(SUBSTITUTE(SUBSTITUTE($E10,";","；"),"；",REPT(" ",100)),301,100)),"") | J10: =IF(ISNUMBER(SEARCH("；",SUBSTITUTE($E10,";","；"))),TRIM(MID(SUBSTITUTE(SUBSTITUTE($E10,";","；"),"；",REPT(" ",100)),401,100)),"") | K10: =IF(ISNUMBER(SEARCH("；",SUBSTITUTE($E10,";","；"))),TRIM(MID(SUBSTITUTE(SUBSTITUTE($E10,";","；"),"；",REPT(" ",100)),501,100)),"") | L10: =IF(ISNUMBER(SEARCH("；",SUBSTITUTE($E10,";","；"))),TRIM(MID(SUBSTITUTE(SUBSTITUTE($E10,";","；"),"；",REPT(" ",100)),601,100)),"") | M10: =IF(ISNUMBER(SEARCH("；",SUBSTITUTE($E10,";","；"))),TRIM(MID(SUBSTITUTE(SUBSTITUTE($E10,";","；"),"；",REPT(" ",100)),701,100)),"") | N10: =IF(ISNUMBER(SEARCH("；",SUBSTITUTE($E10,";","；"))),TRIM(MID(SUBSTITUTE(SUBSTITUTE($E10,";","；"),"；",REPT(" ",100)),801,100)),"") | O10: =IF(ISNUMBER(SEARCH("；",SUBSTITUTE($E10,";","；"))),TRIM(MID(SUBSTITUTE(SUBSTITUTE($E10,";","；"),"；",REPT(" ",100)),901,100)),"") | P10: =IF(AND(配置数据库!$C16="售前填写",INDEX(配置数据库!$G16:$AG16,1,MATCH($B$3,配置数据库!$G$8:$AG$8,0))<>""),SUMPRODUCT((配置数据库!$C$10:$C16="售前填写")*(INDEX(配置数据库!$G$10:$AG16,0,MATCH($B$3,配置数据库!$G$8:$AG$8,0))<>"")),"") | Q10: =IF(AND(配置数据库!$C16="默认配置",INDEX(配置数据库!$G16:$AG16,1,MATCH($B$3,配置数据库!$G$8:$AG$8,0))<>""),SUMPRODUCT((配置数据库!$C$10:$C16="默认配置")*(INDEX(配置数据库!$G$10:$AG16,0,MATCH($B$3,配置数据库!$G$8:$AG$8,0))<>"")),"")
A11: =IFERROR(INDEX(配置数据库!$A:$A,MATCH(2,$P:$P,0)),"") -> 发货时间 | B11: =IF($A11="","",IFERROR(LEFT(SUBSTITUTE(IFERROR(INDEX(配置数据库!$G:$AG,MATCH(2,$P:$P,0),MATCH($B$3,配置数据库!$G$8:$AG$8,0)),""),";","；"),FIND("；",SUBSTITUTE(IFERROR(INDEX(配置数据库!$G:$AG,MATCH(2,$P:$P,0),MATCH($B$3,配置数据库!$G$8:$AG$8,0)),""),";","；"))-1),IFERROR(INDEX(配置数据库!$G:$AG,MATCH(2,$P:$P,0),MATCH($B$3,配置数据库!$G$8:$AG$8,0)),""))) -> 0 | C11: =IF($A11="","","售前填写") -> 售前填写 | D11: =IF($A11="","",IFERROR(INDEX(配置数据库!$B:$B,MATCH(2,$P:$P,0)),"")) -> 0 | E11: =IF($A11="","",IFERROR(INDEX(配置数据库!$G:$AG,MATCH($A11,配置数据库!$A:$A,0),MATCH($B$3,配置数据库!$G$8:$AG$8,0)),"")) -> 0 | F11: =IF(ISNUMBER(SEARCH("；",SUBSTITUTE($E11,";","；"))),TRIM(MID(SUBSTITUTE(SUBSTITUTE($E11,";","；"),"；",REPT(" ",100)),1,100)),"") | G11: =IF(ISNUMBER(SEARCH("；",SUBSTITUTE($E11,";","；"))),TRIM(MID(SUBSTITUTE(SUBSTITUTE($E11,";","；"),"；",REPT(" ",100)),101,100)),"") | H11: =IF(ISNUMBER(SEARCH("；",SUBSTITUTE($E11,";","；"))),TRIM(MID(SUBSTITUTE(SUBSTITUTE($E11,";","；"),"；",REPT(" ",100)),201,100)),"") | I11: =IF(ISNUMBER(SEARCH("；",SUBSTITUTE($E11,";","；"))),TRIM(MID(SUBSTITUTE(SUBSTITUTE($E11,";","；"),"；",REPT(" ",100)),301,100)),"") | J11: =IF(ISNUMBER(SEARCH("；",SUBSTITUTE($E11,";","；"))),TRIM(MID(SUBSTITUTE(SUBSTITUTE($E11,";","；"),"；",REPT(" ",100)),401,100)),"") | K11: =IF(ISNUMBER(SEARCH("；",SUBSTITUTE($E11,";","；"))),TRIM(MID(SUBSTITUTE(SUBSTITUTE($E11,";","；"),"；",REPT(" ",100)),501,100)),"") | L11: =IF(ISNUMBER(SEARCH("；",SUBSTITUTE($E11,";","；"))),TRIM(MID(SUBSTITUTE(SUBSTITUTE($E11,";","；"),"；",REPT(" ",100)),601,100)),"") | M11: =IF(ISNUMBER(SEARCH("；",SUBSTITUTE($E11,";","；"))),TRIM(MID(SUBSTITUTE(SUBSTITUTE($E11,";","；"),"；",REPT(" ",100)),701,100)),"") | N11: =IF(ISNUMBER(SEARCH("；",SUBSTITUTE($E11,";","；"))),TRIM(MID(SUBSTITUTE(SUBSTITUTE($E11,";","；"),"；",REPT(" ",100)),801,100)),"") | O11: =IF(ISNUMBER(SEARCH("；",SUBSTITUTE($E11,";","；"))),TRIM(MID(SUBSTITUTE(SUBSTITUTE($E11,";","；"),"；",REPT(" ",100)),901,100)),"") | P11: =IF(AND(配置数据库!$C19="售前填写",INDEX(配置数据库!$G19:$AG19,1,MATCH($B$3,配置数据库!$G$8:$AG$8,0))<>""),SUMPRODUCT((配置数据库!$C$10:$C19="售前填写")*(INDEX(配置数据库!$G$10:$AG19,0,MATCH($B$3,配置数据库!$G$8:$AG$8,0))<>"")),"") -> 5 | Q11: =IF(AND(配置数据库!$C19="默认配置",INDEX(配置数据库!$G19:$AG19,1,MATCH($B$3,配置数据库!$G$8:$AG$8,0))<>""),SUMPRODUCT((配置数据库!$C$10:$C19="默认配置")*(INDEX(配置数据库!$G$10:$AG19,0,MATCH($B$3,配置数据库!$G$8:$AG$8,0))<>"")),"")
A12: =IFERROR(INDEX(配置数据库!$A:$A,MATCH(3,$P:$P,0)),"") -> 售前 | B12: 铁箱 | C12: =IF($A12="","","售前填写") -> 售前填写 | D12: =IF($A12="","",IFERROR(INDEX(配置数据库!$B:$B,MATCH(3,$P:$P,0)),"")) -> 0 | E12: =IF($A12="","",IFERROR(INDEX(配置数据库!$G:$AG,MATCH($A12,配置数据库!$A:$A,0),MATCH($B$3,配置数据库!$G$8:$AG$8,0)),"")) -> 0 | F12: =IF(ISNUMBER(SEARCH("；",SUBSTITUTE($E12,";","；"))),TRIM(MID(SUBSTITUTE(SUBSTITUTE($E12,";","；"),"；",REPT(" ",100)),1,100)),"") | G12: =IF(ISNUMBER(SEARCH("；",SUBSTITUTE($E12,";","；"))),TRIM(MID(SUBSTITUTE(SUBSTITUTE($E12,";","；"),"；",REPT(" ",100)),101,100)),"") | H12: =IF(ISNUMBER(SEARCH("；",SUBSTITUTE($E12,";","；"))),TRIM(MID(SUBSTITUTE(SUBSTITUTE($E12,";","；"),"；",REPT(" ",100)),201,100)),"") | I12: =IF(ISNUMBER(SEARCH("；",SUBSTITUTE($E12,";","；"))),TRIM(MID(SUBSTITUTE(SUBSTITUTE($E12,";","；"),"；",REPT(" ",100)),301,100)),"") | J12: =IF(ISNUMBER(SEARCH("；",SUBSTITUTE($E12,";","；"))),TRIM(MID(SUBSTITUTE(SUBSTITUTE($E12,";","；"),"；",REPT(" ",100)),401,100)),"") | K12: =IF(ISNUMBER(SEARCH("；",SUBSTITUTE($E12,";","；"))),TRIM(MID(SUBSTITUTE(SUBSTITUTE($E12,";","；"),"；",REPT(" ",100)),501,100)),"") | L12: =IF(ISNUMBER(SEARCH("；",SUBSTITUTE($E12,";","；"))),TRIM(MID(SUBSTITUTE(SUBSTITUTE($E12,";","；"),"；",REPT(" ",100)),601,100)),"") | M12: =IF(ISNUMBER(SEARCH("；",SUBSTITUTE($E12,";","；"))),TRIM(MID(SUBSTITUTE(SUBSTITUTE($E12,";","；"),"；",REPT(" ",100)),701,100)),"") | N12: =IF(ISNUMBER(SEARCH("；",SUBSTITUTE($E12,";","；"))),TRIM(MID(SUBSTITUTE(SUBSTITUTE($E12,";","；"),"；",REPT(" ",100)),801,100)),"") | O12: =IF(ISNUMBER(SEARCH("；",SUBSTITUTE($E12,";","；"))),TRIM(MID(SUBSTITUTE(SUBSTITUTE($E12,";","；"),"；",REPT(" ",100)),901,100)),"") | P12: =IF(AND(配置数据库!$C20="售前填写",INDEX(配置数据库!$G20:$AG20,1,MATCH($B$3,配置数据库!$G$8:$AG$8,0))<>""),SUMPRODUCT((配置数据库!$C$10:$C20="售前填写")*(INDEX(配置数据库!$G$10:$AG20,0,MATCH($B$3,配置数据库!$G$8:$AG$8,0))<>"")),"") | Q12: =IF(AND(配置数据库!$C20="默认配置",INDEX(配置数据库!$G20:$AG20,1,MATCH($B$3,配置数据库!$G$8:$AG$8,0))<>""),SUMPRODUCT((配置数据库!$C$10:$C20="默认配置")*(INDEX(配置数据库!$G$10:$AG20,0,MATCH($B$3,配置数据库!$G$8:$AG$8,0))<>"")),"")
A13: =IFERROR(INDEX(配置数据库!$A:$A,MATCH(4,$P:$P,0)),"") | B13: =IF($A13="","",IFERROR(LEFT(SUBSTITUTE(IFERROR(INDEX(配置数据库!$G:$AG,MATCH(4,$P:$P,0),MATCH($B$3,配置数据库!$G$8:$AG$8,0)),""),";","；"),FIND("；",SUBSTITUTE(IFERROR(INDEX(配置数据库!$G:$AG,MATCH(4,$P:$P,0),MATCH($B$3,配置数据库!$G$8:$AG$8,0)),""),";","；"))-1),IFERROR(INDEX(配置数据库!$G:$AG,MATCH(4,$P:$P,0),MATCH($B$3,配置数据库!$G$8:$AG$8,0)),""))) | C13: =IF($A13="","","售前填写") | D13: =IF($A13="","",IFERROR(INDEX(配置数据库!$B:$B,MATCH(4,$P:$P,0)),"")) | E13: =IF($A13="","",IFERROR(INDEX(配置数据库!$G:$AG,MATCH($A13,配置数据库!$A:$A,0),MATCH($B$3,配置数据库!$G$8:$AG$8,0)),"")) | F13: =IF(ISNUMBER(SEARCH("；",SUBSTITUTE($E13,";","；"))),TRIM(MID(SUBSTITUTE(SUBSTITUTE($E13,";","；"),"；",REPT(" ",100)),1,100)),"") | G13: =IF(ISNUMBER(SEARCH("；",SUBSTITUTE($E13,";","；"))),TRIM(MID(SUBSTITUTE(SUBSTITUTE($E13,";","；"),"；",REPT(" ",100)),101,100)),"") | H13: =IF(ISNUMBER(SEARCH("；",SUBSTITUTE($E13,";","；"))),TRIM(MID(SUBSTITUTE(SUBSTITUTE($E13,";","；"),"；",REPT(" ",100)),201,100)),"") | I13: =IF(ISNUMBER(SEARCH("；",SUBSTITUTE($E13,";","；"))),TRIM(MID(SUBSTITUTE(SUBSTITUTE($E13,";","；"),"；",REPT(" ",100)),301,100)),"") | J13: =IF(ISNUMBER(SEARCH("；",SUBSTITUTE($E13,";","；"))),TRIM(MID(SUBSTITUTE(SUBSTITUTE($E13,";","；"),"；",REPT(" ",100)),401,100)),"") | K13: =IF(ISNUMBER(SEARCH("；",SUBSTITUTE($E13,";","；"))),TRIM(MID(SUBSTITUTE(SUBSTITUTE($E13,";","；"),"；",REPT(" ",100)),501,100)),"") | L13: =IF(ISNUMBER(SEARCH("；",SUBSTITUTE($E13,";","；"))),TRIM(MID(SUBSTITUTE(SUBSTITUTE($E13,";","；"),"；",REPT(" ",100)),601,100)),"") | M13: =IF(ISNUMBER(SEARCH("；",SUBSTITUTE($E13,";","；"))),TRIM(MID(SUBSTITUTE(SUBSTITUTE($E13,";","；"),"；",REPT(" ",100)),701,100)),"") | N13: =IF(ISNUMBER(SEARCH("；",SUBSTITUTE($E13,";","；"))),TRIM(MID(SUBSTITUTE(SUBSTITUTE($E13,";","；"),"；",REPT(" ",100)),801,100)),"") | O13: =IF(ISNUMBER(SEARCH("；",SUBSTITUTE($E13,";","；"))),TRIM(MID(SUBSTITUTE(SUBSTITUTE($E13,";","；"),"；",REPT(" ",100)),901,100)),"") | P13: =IF(AND(配置数据库!#REF!="售前填写",INDEX(配置数据库!#REF!,1,MATCH($B$3,配置数据库!$G$8:$AG$8,0))<>""),SUMPRODUCT((配置数据库!$C$10:$C20="售前填写")*(INDEX(配置数据库!$G$10:$AG20,0,MATCH($B$3,配置数据库!$G$8:$AG$8,0))<>"")),"") -> #REF! | Q13: =IF(AND(配置数据库!#REF!="默认配置",INDEX(配置数据库!#REF!,1,MATCH($B$3,配置数据库!$G$8:$AG$8,0))<>""),SUMPRODUCT((配置数据库!$C$10:$C20="默认配置")*(INDEX(配置数据库!$G$10:$AG20,0,MATCH($B$3,配置数据库!$G$8:$AG$8,0))<>"")),"") -> #REF!
A14: =IFERROR(INDEX(配置数据库!$A:$A,MATCH(5,$P:$P,0)),"") -> 货叉外宽要求（mm） | B14: =IF($A14="","",IFERROR(LEFT(SUBSTITUTE(IFERROR(INDEX(配置数据库!$G:$AG,MATCH(5,$P:$P,0),MATCH($B$3,配置数据库!$G$8:$AG$8,0)),""),";","；"),FIND("；",SUBSTITUTE(IFERROR(INDEX(配置数据库!$G:$AG,MATCH(5,$P:$P,0),MATCH($B$3,配置数据库!$G$8:$AG$8,0)),""),";","；"))-1),IFERROR(INDEX(配置数据库!$G:$AG,MATCH(5,$P:$P,0),MATCH($B$3,配置数据库!$G$8:$AG$8,0)),""))) -> 560/660 | C14: =IF($A14="","","售前填写") -> 售前填写 | D14: =IF($A14="","",IFERROR(INDEX(配置数据库!$B:$B,MATCH(5,$P:$P,0)),"")) | E14: =IF($A14="","",IFERROR(INDEX(配置数据库!$G:$AG,MATCH($A14,配置数据库!$A:$A,0),MATCH($B$3,配置数据库!$G$8:$AG$8,0)),"")) -> 560/660 | F14: =IF(ISNUMBER(SEARCH("；",SUBSTITUTE($E14,";","；"))),TRIM(MID(SUBSTITUTE(SUBSTITUTE($E14,";","；"),"；",REPT(" ",100)),1,100)),"") | G14: =IF(ISNUMBER(SEARCH("；",SUBSTITUTE($E14,";","；"))),TRIM(MID(SUBSTITUTE(SUBSTITUTE($E14,";","；"),"；",REPT(" ",100)),101,100)),"") | H14: =IF(ISNUMBER(SEARCH("；",SUBSTITUTE($E14,";","；"))),TRIM(MID(SUBSTITUTE(SUBSTITUTE($E14,";","；"),"；",REPT(" ",100)),201,100)),"") | I14: =IF(ISNUMBER(SEARCH("；",SUBSTITUTE($E14,";","；"))),TRIM(MID(SUBSTITUTE(SUBSTITUTE($E14,";","；"),"；",REPT(" ",100)),301,100)),"") | J14: =IF(ISNUMBER(SEARCH("；",SUBSTITUTE($E14,";","；"))),TRIM(MID(SUBSTITUTE(SUBSTITUTE($E14,";","；"),"；",REPT(" ",100)),401,100)),"") | K14: =IF(ISNUMBER(SEARCH("；",SUBSTITUTE($E14,";","；"))),TRIM(MID(SUBSTITUTE(SUBSTITUTE($E14,";","；"),"；",REPT(" ",100)),501,100)),"") | L14: =IF(ISNUMBER(SEARCH("；",SUBSTITUTE($E14,";","；"))),TRIM(MID(SUBSTITUTE(SUBSTITUTE($E14,";","；"),"；",REPT(" ",100)),601,100)),"") | M14: =IF(ISNUMBER(SEARCH("；",SUBSTITUTE($E14,";","；"))),TRIM(MID(SUBSTITUTE(SUBSTITUTE($E14,";","；"),"；",REPT(" ",100)),701,100)),"") | N14: =IF(ISNUMBER(SEARCH("；",SUBSTITUTE($E14,";","；"))),TRIM(MID(SUBSTITUTE(SUBSTITUTE($E14,";","；"),"；",REPT(" ",100)),801,100)),"") | O14: =IF(ISNUMBER(SEARCH("；",SUBSTITUTE($E14,";","；"))),TRIM(MID(SUBSTITUTE(SUBSTITUTE($E14,";","；"),"；",REPT(" ",100)),901,100)),"") | P14: =IF(AND(配置数据库!#REF!="售前填写",INDEX(配置数据库!#REF!,1,MATCH($B$3,配置数据库!$G$8:$AG$8,0))<>""),SUMPRODUCT((配置数据库!$C$10:$C20="售前填写")*(INDEX(配置数据库!$G$10:$AG20,0,MATCH($B$3,配置数据库!$G$8:$AG$8,0))<>"")),"") -> #REF! | Q14: =IF(AND(配置数据库!#REF!="默认配置",INDEX(配置数据库!#REF!,1,MATCH($B$3,配置数据库!$G$8:$AG$8,0))<>""),SUMPRODUCT((配置数据库!$C$10:$C20="默认配置")*(INDEX(配置数据库!$G$10:$AG20,0,MATCH($B$3,配置数据库!$G$8:$AG$8,0))<>"")),"") -> #REF!
A15: =IFERROR(INDEX(配置数据库!$A:$A,MATCH(6,$P:$P,0)),"") | B15: =IF($A15="","",IFERROR(LEFT(SUBSTITUTE(IFERROR(INDEX(配置数据库!$G:$AG,MATCH(6,$P:$P,0),MATCH($B$3,配置数据库!$G$8:$AG$8,0)),""),";","；"),FIND("；",SUBSTITUTE(IFERROR(INDEX(配置数据库!$G:$AG,MATCH(6,$P:$P,0),MATCH($B$3,配置数据库!$G$8:$AG$8,0)),""),";","；"))-1),IFERROR(INDEX(配置数据库!$G:$AG,MATCH(6,$P:$P,0),MATCH($B$3,配置数据库!$G$8:$AG$8,0)),""))) | C15: =IF($A15="","","售前填写") | D15: =IF($A15="","",IFERROR(INDEX(配置数据库!$B:$B,MATCH(6,$P:$P,0)),"")) | E15: =IF($A15="","",IFERROR(INDEX(配置数据库!$G:$AG,MATCH($A15,配置数据库!$A:$A,0),MATCH($B$3,配置数据库!$G$8:$AG$8,0)),"")) | F15: =IF(ISNUMBER(SEARCH("；",SUBSTITUTE($E15,";","；"))),TRIM(MID(SUBSTITUTE(SUBSTITUTE($E15,";","；"),"；",REPT(" ",100)),1,100)),"") | G15: =IF(ISNUMBER(SEARCH("；",SUBSTITUTE($E15,";","；"))),TRIM(MID(SUBSTITUTE(SUBSTITUTE($E15,";","；"),"；",REPT(" ",100)),101,100)),"") | H15: =IF(ISNUMBER(SEARCH("；",SUBSTITUTE($E15,";","；"))),TRIM(MID(SUBSTITUTE(SUBSTITUTE($E15,";","；"),"；",REPT(" ",100)),201,100)),"") | I15: =IF(ISNUMBER(SEARCH("；",SUBSTITUTE($E15,";","；"))),TRIM(MID(SUBSTITUTE(SUBSTITUTE($E15,";","；"),"；",REPT(" ",100)),301,100)),"") | J15: =IF(ISNUMBER(SEARCH("；",SUBSTITUTE($E15,";","；"))),TRIM(MID(SUBSTITUTE(SUBSTITUTE($E15,";","；"),"；",REPT(" ",100)),401,100)),"") | K15: =IF(ISNUMBER(SEARCH("；",SUBSTITUTE($E15,";","；"))),TRIM(MID(SUBSTITUTE(SUBSTITUTE($E15,";","；"),"；",REPT(" ",100)),501,100)),"") | L15: =IF(ISNUMBER(SEARCH("；",SUBSTITUTE($E15,";","；"))),TRIM(MID(SUBSTITUTE(SUBSTITUTE($E15,";","；"),"；",REPT(" ",100)),601,100)),"") | M15: =IF(ISNUMBER(SEARCH("；",SUBSTITUTE($E15,";","；"))),TRIM(MID(SUBSTITUTE(SUBSTITUTE($E15,";","；"),"；",REPT(" ",100)),701,100)),"") | N15: =IF(ISNUMBER(SEARCH("；",SUBSTITUTE($E15,";","；"))),TRIM(MID(SUBSTITUTE(SUBSTITUTE($E15,";","；"),"；",REPT(" ",100)),801,100)),"") | O15: =IF(ISNUMBER(SEARCH("；",SUBSTITUTE($E15,";","；"))),TRIM(MID(SUBSTITUTE(SUBSTITUTE($E15,";","；"),"；",REPT(" ",100)),901,100)),"") | P15: =IF(AND(配置数据库!$C21="售前填写",INDEX(配置数据库!$G21:$AG21,1,MATCH($B$3,配置数据库!$G$8:$AG$8,0))<>""),SUMPRODUCT((配置数据库!$C$10:$C21="售前填写")*(INDEX(配置数据库!$G$10:$AG21,0,MATCH($B$3,配置数据库!$G$8:$AG$8,0))<>"")),"") | Q15: =IF(AND(配置数据库!$C21="默认配置",INDEX(配置数据库!$G21:$AG21,1,MATCH($B$3,配置数据库!$G$8:$AG$8,0))<>""),SUMPRODUCT((配置数据库!$C$10:$C21="默认配置")*(INDEX(配置数据库!$G$10:$AG21,0,MATCH($B$3,配置数据库!$G$8:$AG$8,0))<>"")),"")
A16: =IFERROR(INDEX(配置数据库!$A:$A,MATCH(7,$P:$P,0)),"") | B16: =IF($A16="","",IFERROR(LEFT(SUBSTITUTE(IFERROR(INDEX(配置数据库!$G:$AG,MATCH(7,$P:$P,0),MATCH($B$3,配置数据库!$G$8:$AG$8,0)),""),";","；"),FIND("；",SUBSTITUTE(IFERROR(INDEX(配置数据库!$G:$AG,MATCH(7,$P:$P,0),MATCH($B$3,配置数据库!$G$8:$AG$8,0)),""),";","；"))-1),IFERROR(INDEX(配置数据库!$G:$AG,MATCH(7,$P:$P,0),MATCH($B$3,配置数据库!$G$8:$AG$8,0)),""))) | C16: =IF($A16="","","售前填写") | D16: =IF($A16="","",IFERROR(INDEX(配置数据库!$B:$B,MATCH(7,$P:$P,0)),"")) | E16: =IF($A16="","",IFERROR(INDEX(配置数据库!$G:$AG,MATCH($A16,配置数据库!$A:$A,0),MATCH($B$3,配置数据库!$G$8:$AG$8,0)),"")) | F16: =IF(ISNUMBER(SEARCH("；",SUBSTITUTE($E16,";","；"))),TRIM(MID(SUBSTITUTE(SUBSTITUTE($E16,";","；"),"；",REPT(" ",100)),1,100)),"") | G16: =IF(ISNUMBER(SEARCH("；",SUBSTITUTE($E16,";","；"))),TRIM(MID(SUBSTITUTE(SUBSTITUTE($E16,";","；"),"；",REPT(" ",100)),101,100)),"") | H16: =IF(ISNUMBER(SEARCH("；",SUBSTITUTE($E16,";","；"))),TRIM(MID(SUBSTITUTE(SUBSTITUTE($E16,";","；"),"；",REPT(" ",100)),201,100)),"") | I16: =IF(ISNUMBER(SEARCH("；",SUBSTITUTE($E16,";","；"))),TRIM(MID(SUBSTITUTE(SUBSTITUTE($E16,";","；"),"；",REPT(" ",100)),301,100)),"") | J16: =IF(ISNUMBER(SEARCH("；",SUBSTITUTE($E16,";","；"))),TRIM(MID(SUBSTITUTE(SUBSTITUTE($E16,";","；"),"；",REPT(" ",100)),401,100)),"") | K16: =IF(ISNUMBER(SEARCH("；",SUBSTITUTE($E16,";","；"))),TRIM(MID(SUBSTITUTE(SUBSTITUTE($E16,";","；"),"；",REPT(" ",100)),501,100)),"") | L16: =IF(ISNUMBER(SEARCH("；",SUBSTITUTE($E16,";","；"))),TRIM(MID(SUBSTITUTE(SUBSTITUTE($E16,";","；"),"；",REPT(" ",100)),601,100)),"") | M16: =IF(ISNUMBER(SEARCH("；",SUBSTITUTE($E16,";","；"))),TRIM(MID(SUBSTITUTE(SUBSTITUTE($E16,";","；"),"；",REPT(" ",100)),701,100)),"") | N16: =IF(ISNUMBER(SEARCH("；",SUBSTITUTE($E16,";","；"))),TRIM(MID(SUBSTITUTE(SUBSTITUTE($E16,";","；"),"；",REPT(" ",100)),801,100)),"") | O16: =IF(ISNUMBER(SEARCH("；",SUBSTITUTE($E16,";","；"))),TRIM(MID(SUBSTITUTE(SUBSTITUTE($E16,";","；"),"；",REPT(" ",100)),901,100)),"") | P16: =IF(AND(配置数据库!$C22="售前填写",INDEX(配置数据库!$G22:$AG22,1,MATCH($B$3,配置数据库!$G$8:$AG$8,0))<>""),SUMPRODUCT((配置数据库!$C$10:$C22="售前填写")*(INDEX(配置数据库!$G$10:$AG22,0,MATCH($B$3,配置数据库!$G$8:$AG$8,0))<>"")),"") | Q16: =IF(AND(配置数据库!$C22="默认配置",INDEX(配置数据库!$G22:$AG22,1,MATCH($B$3,配置数据库!$G$8:$AG$8,0))<>""),SUMPRODUCT((配置数据库!$C$10:$C22="默认配置")*(INDEX(配置数据库!$G$10:$AG22,0,MATCH($B$3,配置数据库!$G$8:$AG$8,0))<>"")),"")
A17: =IFERROR(INDEX(配置数据库!$A:$A,MATCH(8,$P:$P,0)),"") -> 托盘驼峰 | B17: =IF($A17="","",IFERROR(LEFT(SUBSTITUTE(IFERROR(INDEX(配置数据库!$G:$AG,MATCH(8,$P:$P,0),MATCH($B$3,配置数据库!$G$8:$AG$8,0)),""),";","；"),FIND("；",SUBSTITUTE(IFERROR(INDEX(配置数据库!$G:$AG,MATCH(8,$P:$P,0),MATCH($B$3,配置数据库!$G$8:$AG$8,0)),""),";","；"))-1),IFERROR(INDEX(配置数据库!$G:$AG,MATCH(8,$P:$P,0),MATCH($B$3,配置数据库!$G$8:$AG$8,0)),""))) -> 0 | C17: =IF($A17="","","售前填写") -> 售前填写 | D17: =IF($A17="","",IFERROR(INDEX(配置数据库!$B:$B,MATCH(8,$P:$P,0)),"")) -> 0 | E17: =IF($A17="","",IFERROR(INDEX(配置数据库!$G:$AG,MATCH($A17,配置数据库!$A:$A,0),MATCH($B$3,配置数据库!$G$8:$AG$8,0)),"")) -> 0 | F17: =IF(ISNUMBER(SEARCH("；",SUBSTITUTE($E17,";","；"))),TRIM(MID(SUBSTITUTE(SUBSTITUTE($E17,";","；"),"；",REPT(" ",100)),1,100)),"") | G17: =IF(ISNUMBER(SEARCH("；",SUBSTITUTE($E17,";","；"))),TRIM(MID(SUBSTITUTE(SUBSTITUTE($E17,";","；"),"；",REPT(" ",100)),101,100)),"") | H17: =IF(ISNUMBER(SEARCH("；",SUBSTITUTE($E17,";","；"))),TRIM(MID(SUBSTITUTE(SUBSTITUTE($E17,";","；"),"；",REPT(" ",100)),201,100)),"") | I17: =IF(ISNUMBER(SEARCH("；",SUBSTITUTE($E17,";","；"))),TRIM(MID(SUBSTITUTE(SUBSTITUTE($E17,";","；"),"；",REPT(" ",100)),301,100)),"") | J17: =IF(ISNUMBER(SEARCH("；",SUBSTITUTE($E17,";","；"))),TRIM(MID(SUBSTITUTE(SUBSTITUTE($E17,";","；"),"；",REPT(" ",100)),401,100)),"") | K17: =IF(ISNUMBER(SEARCH("；",SUBSTITUTE($E17,";","；"))),TRIM(MID(SUBSTITUTE(SUBSTITUTE($E17,";","；"),"；",REPT(" ",100)),501,100)),"") | L17: =IF(ISNUMBER(SEARCH("；",SUBSTITUTE($E17,";","；"))),TRIM(MID(SUBSTITUTE(SUBSTITUTE($E17,";","；"),"；",REPT(" ",100)),601,100)),"") | M17: =IF(ISNUMBER(SEARCH("；",SUBSTITUTE($E17,";","；"))),TRIM(MID(SUBSTITUTE(SUBSTITUTE($E17,";","；"),"；",REPT(" ",100)),701,100)),"") | N17: =IF(ISNUMBER(SEARCH("；",SUBSTITUTE($E17,";","；"))),TRIM(MID(SUBSTITUTE(SUBSTITUTE($E17,";","；"),"；",REPT(" ",100)),801,100)),"") | O17: =IF(ISNUMBER(SEARCH("；",SUBSTITUTE($E17,";","；"))),TRIM(MID(SUBSTITUTE(SUBSTITUTE($E17,";","；"),"；",REPT(" ",100)),901,100)),"") | P17: =IF(AND(配置数据库!$C23="售前填写",INDEX(配置数据库!$G23:$AG23,1,MATCH($B$3,配置数据库!$G$8:$AG$8,0))<>""),SUMPRODUCT((配置数据库!$C$10:$C23="售前填写")*(INDEX(配置数据库!$G$10:$AG23,0,MATCH($B$3,配置数据库!$G$8:$AG$8,0))<>"")),"") | Q17: =IF(AND(配置数据库!$C23="默认配置",INDEX(配置数据库!$G23:$AG23,1,MATCH($B$3,配置数据库!$G$8:$AG$8,0))<>""),SUMPRODUCT((配置数据库!$C$10:$C23="默认配置")*(INDEX(配置数据库!$G$10:$AG23,0,MATCH($B$3,配置数据库!$G$8:$AG$8,0))<>"")),"")
A18: =IFERROR(INDEX(配置数据库!$A:$A,MATCH(9,$P:$P,0)),"") | C18: =IF($A18="","","售前填写") | D18: =IF($A18="","",IFERROR(INDEX(配置数据库!$B:$B,MATCH(9,$P:$P,0)),"")) | E18: =IF($A18="","",IFERROR(INDEX(配置数据库!$G:$AG,MATCH($A18,配置数据库!$A:$A,0),MATCH($B$3,配置数据库!$G$8:$AG$8,0)),"")) | F18: =IF(ISNUMBER(SEARCH("；",SUBSTITUTE($E18,";","；"))),TRIM(MID(SUBSTITUTE(SUBSTITUTE($E18,";","；"),"；",REPT(" ",100)),1,100)),"") | G18: =IF(ISNUMBER(SEARCH("；",SUBSTITUTE($E18,";","；"))),TRIM(MID(SUBSTITUTE(SUBSTITUTE($E18,";","；"),"；",REPT(" ",100)),101,100)),"") | H18: =IF(ISNUMBER(SEARCH("；",SUBSTITUTE($E18,";","；"))),TRIM(MID(SUBSTITUTE(SUBSTITUTE($E18,";","；"),"；",REPT(" ",100)),201,100)),"") | I18: =IF(ISNUMBER(SEARCH("；",SUBSTITUTE($E18,";","；"))),TRIM(MID(SUBSTITUTE(SUBSTITUTE($E18,";","；"),"；",REPT(" ",100)),301,100)),"") | J18: =IF(ISNUMBER(SEARCH("；",SUBSTITUTE($E18,";","；"))),TRIM(MID(SUBSTITUTE(SUBSTITUTE($E18,";","；"),"；",REPT(" ",100)),401,100)),"") | K18: =IF(ISNUMBER(SEARCH("；",SUBSTITUTE($E18,";","；"))),TRIM(MID(SUBSTITUTE(SUBSTITUTE($E18,";","；"),"；",REPT(" ",100)),501,100)),"") | L18: =IF(ISNUMBER(SEARCH("；",SUBSTITUTE($E18,";","；"))),TRIM(MID(SUBSTITUTE(SUBSTITUTE($E18,";","；"),"；",REPT(" ",100)),601,100)),"") | M18: =IF(ISNUMBER(SEARCH("；",SUBSTITUTE($E18,";","；"))),TRIM(MID(SUBSTITUTE(SUBSTITUTE($E18,";","；"),"；",REPT(" ",100)),701,100)),"") | N18: =IF(ISNUMBER(SEARCH("；",SUBSTITUTE($E18,";","；"))),TRIM(MID(SUBSTITUTE(SUBSTITUTE($E18,";","；"),"；",REPT(" ",100)),801,100)),"") | O18: =IF(ISNUMBER(SEARCH("；",SUBSTITUTE($E18,";","；"))),TRIM(MID(SUBSTITUTE(SUBSTITUTE($E18,";","；"),"；",REPT(" ",100)),901,100)),"") | P18: =IF(AND(配置数据库!$C24="售前填写",INDEX(配置数据库!$G24:$AG24,1,MATCH($B$3,配置数据库!$G$8:$AG$8,0))<>""),SUMPRODUCT((配置数据库!$C$10:$C24="售前填写")*(INDEX(配置数据库!$G$10:$AG24,0,MATCH($B$3,配置数据库!$G$8:$AG$8,0))<>"")),"") | Q18: =IF(AND(配置数据库!$C24="默认配置",INDEX(配置数据库!$G24:$AG24,1,MATCH($B$3,配置数据库!$G$8:$AG$8,0))<>""),SUMPRODUCT((配置数据库!$C$10:$C24="默认配置")*(INDEX(配置数据库!$G$10:$AG24,0,MATCH($B$3,配置数据库!$G$8:$AG$8,0))<>"")),"")
A19: =IFERROR(INDEX(配置数据库!$A:$A,MATCH(10,$P:$P,0)),"") -> 牵引机构 | B19: =IF($A19="","",IFERROR(LEFT(SUBSTITUTE(IFERROR(INDEX(配置数据库!$G:$AG,MATCH(10,$P:$P,0),MATCH($B$3,配置数据库!$G$8:$AG$8,0)),""),";","；"),FIND("；",SUBSTITUTE(IFERROR(INDEX(配置数据库!$G:$AG,MATCH(10,$P:$P,0),MATCH($B$3,配置数据库!$G$8:$AG$8,0)),""),";","；"))-1),IFERROR(INDEX(配置数据库!$G:$AG,MATCH(10,$P:$P,0),MATCH($B$3,配置数据库!$G$8:$AG$8,0)),""))) | C19: =IF($A19="","","售前填写") -> 售前填写 | D19: =IF($A19="","",IFERROR(INDEX(配置数据库!$B:$B,MATCH(10,$P:$P,0)),"")) | E19: =IF($A19="","",IFERROR(INDEX(配置数据库!$G:$AG,MATCH($A19,配置数据库!$A:$A,0),MATCH($B$3,配置数据库!$G$8:$AG$8,0)),"")) | F19: =IF(ISNUMBER(SEARCH("；",SUBSTITUTE($E19,";","；"))),TRIM(MID(SUBSTITUTE(SUBSTITUTE($E19,";","；"),"；",REPT(" ",100)),1,100)),"") | G19: =IF(ISNUMBER(SEARCH("；",SUBSTITUTE($E19,";","；"))),TRIM(MID(SUBSTITUTE(SUBSTITUTE($E19,";","；"),"；",REPT(" ",100)),101,100)),"") | H19: =IF(ISNUMBER(SEARCH("；",SUBSTITUTE($E19,";","；"))),TRIM(MID(SUBSTITUTE(SUBSTITUTE($E19,";","；"),"；",REPT(" ",100)),201,100)),"") | I19: =IF(ISNUMBER(SEARCH("；",SUBSTITUTE($E19,";","；"))),TRIM(MID(SUBSTITUTE(SUBSTITUTE($E19,";","；"),"；",REPT(" ",100)),301,100)),"") | J19: =IF(ISNUMBER(SEARCH("；",SUBSTITUTE($E19,";","；"))),TRIM(MID(SUBSTITUTE(SUBSTITUTE($E19,";","；"),"；",REPT(" ",100)),401,100)),"") | K19: =IF(ISNUMBER(SEARCH("；",SUBSTITUTE($E19,";","；"))),TRIM(MID(SUBSTITUTE(SUBSTITUTE($E19,";","；"),"；",REPT(" ",100)),501,100)),"") | L19: =IF(ISNUMBER(SEARCH("；",SUBSTITUTE($E19,";","；"))),TRIM(MID(SUBSTITUTE(SUBSTITUTE($E19,";","；"),"；",REPT(" ",100)),601,100)),"") | M19: =IF(ISNUMBER(SEARCH("；",SUBSTITUTE($E19,";","；"))),TRIM(MID(SUBSTITUTE(SUBSTITUTE($E19,";","；"),"；",REPT(" ",100)),701,100)),"") | N19: =IF(ISNUMBER(SEARCH("；",SUBSTITUTE($E19,";","；"))),TRIM(MID(SUBSTITUTE(SUBSTITUTE($E19,";","；"),"；",REPT(" ",100)),801,100)),"") | O19: =IF(ISNUMBER(SEARCH("；",SUBSTITUTE($E19,";","；"))),TRIM(MID(SUBSTITUTE(SUBSTITUTE($E19,";","；"),"；",REPT(" ",100)),901,100)),"") | P19: =IF(AND(配置数据库!#REF!="售前填写",INDEX(配置数据库!#REF!,1,MATCH($B$3,配置数据库!$G$8:$AG$8,0))<>""),SUMPRODUCT((配置数据库!$C$10:$C24="售前填写")*(INDEX(配置数据库!$G$10:$AG24,0,MATCH($B$3,配置数据库!$G$8:$AG$8,0))<>"")),"") -> #REF! | Q19: =IF(AND(配置数据库!#REF!="默认配置",INDEX(配置数据库!#REF!,1,MATCH($B$3,配置数据库!$G$8:$AG$8,0))<>""),SUMPRODUCT((配置数据库!$C$10:$C24="默认配置")*(INDEX(配置数据库!$G$10:$AG24,0,MATCH($B$3,配置数据库!$G$8:$AG$8,0))<>"")),"") -> #REF!
A20: =IFERROR(INDEX(配置数据库!$A:$A,MATCH(11,$P:$P,0)),"") | B20: =IF($A20="","",IFERROR(LEFT(SUBSTITUTE(IFERROR(INDEX(配置数据库!$G:$AG,MATCH(11,$P:$P,0),MATCH($B$3,配置数据库!$G$8:$AG$8,0)),""),";","；"),FIND("；",SUBSTITUTE(IFERROR(INDEX(配置数据库!$G:$AG,MATCH(11,$P:$P,0),MATCH($B$3,配置数据库!$G$8:$AG$8,0)),""),";","；"))-1),IFERROR(INDEX(配置数据库!$G:$AG,MATCH(11,$P:$P,0),MATCH($B$3,配置数据库!$G$8:$AG$8,0)),""))) | C20: =IF($A20="","","售前填写") | D20: =IF($A20="","",IFERROR(INDEX(配置数据库!$B:$B,MATCH(11,$P:$P,0)),"")) | E20: =IF($A20="","",IFERROR(INDEX(配置数据库!$G:$AG,MATCH($A20,配置数据库!$A:$A,0),MATCH($B$3,配置数据库!$G$8:$AG$8,0)),"")) | F20: =IF(ISNUMBER(SEARCH("；",SUBSTITUTE($E20,";","；"))),TRIM(MID(SUBSTITUTE(SUBSTITUTE($E20,";","；"),"；",REPT(" ",100)),1,100)),"") | G20: =IF(ISNUMBER(SEARCH("；",SUBSTITUTE($E20,";","；"))),TRIM(MID(SUBSTITUTE(SUBSTITUTE($E20,";","；"),"；",REPT(" ",100)),101,100)),"") | H20: =IF(ISNUMBER(SEARCH("；",SUBSTITUTE($E20,";","；"))),TRIM(MID(SUBSTITUTE(SUBSTITUTE($E20,";","；"),"；",REPT(" ",100)),201,100)),"") | I20: =IF(ISNUMBER(SEARCH("；",SUBSTITUTE($E20,";","；"))),TRIM(MID(SUBSTITUTE(SUBSTITUTE($E20,";","；"),"；",REPT(" ",100)),301,100)),"") | J20: =IF(ISNUMBER(SEARCH("；",SUBSTITUTE($E20,";","；"))),TRIM(MID(SUBSTITUTE(SUBSTITUTE($E20,";","；"),"；",REPT(" ",100)),401,100)),"") | K20: =IF(ISNUMBER(SEARCH("；",SUBSTITUTE($E20,";","；"))),TRIM(MID(SUBSTITUTE(SUBSTITUTE($E20,";","；"),"；",REPT(" ",100)),501,100)),"") | L20: =IF(ISNUMBER(SEARCH("；",SUBSTITUTE($E20,";","；"))),TRIM(MID(SUBSTITUTE(SUBSTITUTE($E20,";","；"),"；",REPT(" ",100)),601,100)),"") | M20: =IF(ISNUMBER(SEARCH("；",SUBSTITUTE($E20,";","；"))),TRIM(MID(SUBSTITUTE(SUBSTITUTE($E20,";","；"),"；",REPT(" ",100)),701,100)),"") | N20: =IF(ISNUMBER(SEARCH("；",SUBSTITUTE($E20,";","；"))),TRIM(MID(SUBSTITUTE(SUBSTITUTE($E20,";","；"),"；",REPT(" ",100)),801,100)),"") | O20: =IF(ISNUMBER(SEARCH("；",SUBSTITUTE($E20,";","；"))),TRIM(MID(SUBSTITUTE(SUBSTITUTE($E20,";","；"),"；",REPT(" ",100)),901,100)),"") | P20: =IF(AND(配置数据库!#REF!="售前填写",INDEX(配置数据库!#REF!,1,MATCH($B$3,配置数据库!$G$8:$AG$8,0))<>""),SUMPRODUCT((配置数据库!$C$10:$C24="售前填写")*(INDEX(配置数据库!$G$10:$AG24,0,MATCH($B$3,配置数据库!$G$8:$AG$8,0))<>"")),"") -> #REF! | Q20: =IF(AND(配置数据库!#REF!="默认配置",INDEX(配置数据库!#REF!,1,MATCH($B$3,配置数据库!$G$8:$AG$8,0))<>""),SUMPRODUCT((配置数据库!$C$10:$C24="默认配置")*(INDEX(配置数据库!$G$10:$AG24,0,MATCH($B$3,配置数据库!$G$8:$AG$8,0))<>"")),"") -> #REF!
A21: =IFERROR(INDEX(配置数据库!$A:$A,MATCH(12,$P:$P,0)),"") | B21: =IF($A21="","",IFERROR(LEFT(SUBSTITUTE(IFERROR(INDEX(配置数据库!$G:$AG,MATCH(12,$P:$P,0),MATCH($B$3,配置数据库!$G$8:$AG$8,0)),""),";","；"),FIND("；",SUBSTITUTE(IFERROR(INDEX(配置数据库!$G:$AG,MATCH(12,$P:$P,0),MATCH($B$3,配置数据库!$G$8:$AG$8,0)),""),";","；"))-1),IFERROR(INDEX(配置数据库!$G:$AG,MATCH(12,$P:$P,0),MATCH($B$3,配置数据库!$G$8:$AG$8,0)),""))) | C21: =IF($A21="","","售前填写") | D21: =IF($A21="","",IFERROR(INDEX(配置数据库!$B:$B,MATCH(12,$P:$P,0)),"")) | E21: =IF($A21="","",IFERROR(INDEX(配置数据库!$G:$AG,MATCH($A21,配置数据库!$A:$A,0),MATCH($B$3,配置数据库!$G$8:$AG$8,0)),"")) | F21: =IF(ISNUMBER(SEARCH("；",SUBSTITUTE($E21,";","；"))),TRIM(MID(SUBSTITUTE(SUBSTITUTE($E21,";","；"),"；",REPT(" ",100)),1,100)),"") | G21: =IF(ISNUMBER(SEARCH("；",SUBSTITUTE($E21,";","；"))),TRIM(MID(SUBSTITUTE(SUBSTITUTE($E21,";","；"),"；",REPT(" ",100)),101,100)),"") | H21: =IF(ISNUMBER(SEARCH("；",SUBSTITUTE($E21,";","；"))),TRIM(MID(SUBSTITUTE(SUBSTITUTE($E21,";","；"),"；",REPT(" ",100)),201,100)),"") | I21: =IF(ISNUMBER(SEARCH("；",SUBSTITUTE($E21,";","；"))),TRIM(MID(SUBSTITUTE(SUBSTITUTE($E21,";","；"),"；",REPT(" ",100)),301,100)),"") | J21: =IF(ISNUMBER(SEARCH("；",SUBSTITUTE($E21,";","；"))),TRIM(MID(SUBSTITUTE(SUBSTITUTE($E21,";","；"),"；",REPT(" ",100)),401,100)),"") | K21: =IF(ISNUMBER(SEARCH("；",SUBSTITUTE($E21,";","；"))),TRIM(MID(SUBSTITUTE(SUBSTITUTE($E21,";","；"),"；",REPT(" ",100)),501,100)),"") | L21: =IF(ISNUMBER(SEARCH("；",SUBSTITUTE($E21,";","；"))),TRIM(MID(SUBSTITUTE(SUBSTITUTE($E21,";","；"),"；",REPT(" ",100)),601,100)),"") | M21: =IF(ISNUMBER(SEARCH("；",SUBSTITUTE($E21,";","；"))),TRIM(MID(SUBSTITUTE(SUBSTITUTE($E21,";","；"),"；",REPT(" ",100)),701,100)),"") | N21: =IF(ISNUMBER(SEARCH("；",SUBSTITUTE($E21,";","；"))),TRIM(MID(SUBSTITUTE(SUBSTITUTE($E21,";","；"),"；",REPT(" ",100)),801,100)),"") | O21: =IF(ISNUMBER(SEARCH("；",SUBSTITUTE($E21,";","；"))),TRIM(MID(SUBSTITUTE(SUBSTITUTE($E21,";","；"),"；",REPT(" ",100)),901,100)),"") | P21: =IF(AND(配置数据库!$C97="售前填写",INDEX(配置数据库!$G97:$AG97,1,MATCH($B$3,配置数据库!$G$8:$AG$8,0))<>""),SUMPRODUCT((配置数据库!$C$10:$C97="售前填写")*(INDEX(配置数据库!$G$10:$AG97,0,MATCH($B$3,配置数据库!$G$8:$AG$8,0))<>"")),"") | Q21: =IF(AND(配置数据库!$C97="默认配置",INDEX(配置数据库!$G97:$AG97,1,MATCH($B$3,配置数据库!$G$8:$AG$8,0))<>""),SUMPRODUCT((配置数据库!$C$10:$C97="默认配置")*(INDEX(配置数据库!$G$10:$AG97,0,MATCH($B$3,配置数据库!$G$8:$AG$8,0))<>"")),"") -> 30
A22: =IFERROR(INDEX(配置数据库!$A:$A,MATCH(13,$P:$P,0)),"") | B22: =IF($A22="","",IFERROR(LEFT(SUBSTITUTE(IFERROR(INDEX(配置数据库!$G:$AG,MATCH(13,$P:$P,0),MATCH($B$3,配置数据库!$G$8:$AG$8,0)),""),";","；"),FIND("；",SUBSTITUTE(IFERROR(INDEX(配置数据库!$G:$AG,MATCH(13,$P:$P,0),MATCH($B$3,配置数据库!$G$8:$AG$8,0)),""),";","；"))-1),IFERROR(INDEX(配置数据库!$G:$AG,MATCH(13,$P:$P,0),MATCH($B$3,配置数据库!$G$8:$AG$8,0)),""))) | C22: =IF($A22="","","售前填写") | D22: =IF($A22="","",IFERROR(INDEX(配置数据库!$B:$B,MATCH(13,$P:$P,0)),"")) | E22: =IF($A22="","",IFERROR(INDEX(配置数据库!$G:$AG,MATCH($A22,配置数据库!$A:$A,0),MATCH($B$3,配置数据库!$G$8:$AG$8,0)),"")) | F22: =IF(ISNUMBER(SEARCH("；",SUBSTITUTE($E22,";","；"))),TRIM(MID(SUBSTITUTE(SUBSTITUTE($E22,";","；"),"；",REPT(" ",100)),1,100)),"") | G22: =IF(ISNUMBER(SEARCH("；",SUBSTITUTE($E22,";","；"))),TRIM(MID(SUBSTITUTE(SUBSTITUTE($E22,";","；"),"；",REPT(" ",100)),101,100)),"") | H22: =IF(ISNUMBER(SEARCH("；",SUBSTITUTE($E22,";","；"))),TRIM(MID(SUBSTITUTE(SUBSTITUTE($E22,";","；"),"；",REPT(" ",100)),201,100)),"") | I22: =IF(ISNUMBER(SEARCH("；",SUBSTITUTE($E22,";","；"))),TRIM(MID(SUBSTITUTE(SUBSTITUTE($E22,";","；"),"；",REPT(" ",100)),301,100)),"") | J22: =IF(ISNUMBER(SEARCH("；",SUBSTITUTE($E22,";","；"))),TRIM(MID(SUBSTITUTE(SUBSTITUTE($E22,";","；"),"；",REPT(" ",100)),401,100)),"") | K22: =IF(ISNUMBER(SEARCH("；",SUBSTITUTE($E22,";","；"))),TRIM(MID(SUBSTITUTE(SUBSTITUTE($E22,";","；"),"；",REPT(" ",100)),501,100)),"") | L22: =IF(ISNUMBER(SEARCH("；",SUBSTITUTE($E22,";","；"))),TRIM(MID(SUBSTITUTE(SUBSTITUTE($E22,";","；"),"；",REPT(" ",100)),601,100)),"") | M22: =IF(ISNUMBER(SEARCH("；",SUBSTITUTE($E22,";","；"))),TRIM(MID(SUBSTITUTE(SUBSTITUTE($E22,";","；"),"；",REPT(" ",100)),701,100)),"") | N22: =IF(ISNUMBER(SEARCH("；",SUBSTITUTE($E22,";","；"))),TRIM(MID(SUBSTITUTE(SUBSTITUTE($E22,";","；"),"；",REPT(" ",100)),801,100)),"") | O22: =IF(ISNUMBER(SEARCH("；",SUBSTITUTE($E22,";","；"))),TRIM(MID(SUBSTITUTE(SUBSTITUTE($E22,";","；"),"；",REPT(" ",100)),901,100)),"") | P22: =IF(AND(配置数据库!$C98="售前填写",INDEX(配置数据库!$G98:$AG98,1,MATCH($B$3,配置数据库!$G$8:$AG$8,0))<>""),SUMPRODUCT((配置数据库!$C$10:$C98="售前填写")*(INDEX(配置数据库!$G$10:$AG98,0,MATCH($B$3,配置数据库!$G$8:$AG$8,0))<>"")),"") -> 15 | Q22: =IF(AND(配置数据库!$C98="默认配置",INDEX(配置数据库!$G98:$AG98,1,MATCH($B$3,配置数据库!$G$8:$AG$8,0))<>""),SUMPRODUCT((配置数据库!$C$10:$C98="默认配置")*(INDEX(配置数据库!$G$10:$AG98,0,MATCH($B$3,配置数据库!$G$8:$AG$8,0))<>"")),"")
A23: =IFERROR(INDEX(配置数据库!$A:$A,MATCH(14,$P:$P,0)),"") | B23: =IF($A23="","",IFERROR(LEFT(SUBSTITUTE(IFERROR(INDEX(配置数据库!$G:$AG,MATCH(14,$P:$P,0),MATCH($B$3,配置数据库!$G$8:$AG$8,0)),""),";","；"),FIND("；",SUBSTITUTE(IFERROR(INDEX(配置数据库!$G:$AG,MATCH(14,$P:$P,0),MATCH($B$3,配置数据库!$G$8:$AG$8,0)),""),";","；"))-1),IFERROR(INDEX(配置数据库!$G:$AG,MATCH(14,$P:$P,0),MATCH($B$3,配置数据库!$G$8:$AG$8,0)),""))) | C23: =IF($A23="","","售前填写") | D23: =IF($A23="","",IFERROR(INDEX(配置数据库!$B:$B,MATCH(14,$P:$P,0)),"")) | E23: =IF($A23="","",IFERROR(INDEX(配置数据库!$G:$AG,MATCH($A23,配置数据库!$A:$A,0),MATCH($B$3,配置数据库!$G$8:$AG$8,0)),"")) | F23: =IF(ISNUMBER(SEARCH("；",SUBSTITUTE($E23,";","；"))),TRIM(MID(SUBSTITUTE(SUBSTITUTE($E23,";","；"),"；",REPT(" ",100)),1,100)),"") | G23: =IF(ISNUMBER(SEARCH("；",SUBSTITUTE($E23,";","；"))),TRIM(MID(SUBSTITUTE(SUBSTITUTE($E23,";","；"),"；",REPT(" ",100)),101,100)),"") | H23: =IF(ISNUMBER(SEARCH("；",SUBSTITUTE($E23,";","；"))),TRIM(MID(SUBSTITUTE(SUBSTITUTE($E23,";","；"),"；",REPT(" ",100)),201,100)),"") | I23: =IF(ISNUMBER(SEARCH("；",SUBSTITUTE($E23,";","；"))),TRIM(MID(SUBSTITUTE(SUBSTITUTE($E23,";","；"),"；",REPT(" ",100)),301,100)),"") | J23: =IF(ISNUMBER(SEARCH("；",SUBSTITUTE($E23,";","；"))),TRIM(MID(SUBSTITUTE(SUBSTITUTE($E23,";","；"),"；",REPT(" ",100)),401,100)),"") | K23: =IF(ISNUMBER(SEARCH("；",SUBSTITUTE($E23,";","；"))),TRIM(MID(SUBSTITUTE(SUBSTITUTE($E23,";","；"),"；",REPT(" ",100)),501,100)),"") | L23: =IF(ISNUMBER(SEARCH("；",SUBSTITUTE($E23,";","；"))),TRIM(MID(SUBSTITUTE(SUBSTITUTE($E23,";","；"),"；",REPT(" ",100)),601,100)),"") | M23: =IF(ISNUMBER(SEARCH("；",SUBSTITUTE($E23,";","；"))),TRIM(MID(SUBSTITUTE(SUBSTITUTE($E23,";","；"),"；",REPT(" ",100)),701,100)),"") | N23: =IF(ISNUMBER(SEARCH("；",SUBSTITUTE($E23,";","；"))),TRIM(MID(SUBSTITUTE(SUBSTITUTE($E23,";","；"),"；",REPT(" ",100)),801,100)),"") | O23: =IF(ISNUMBER(SEARCH("；",SUBSTITUTE($E23,";","；"))),TRIM(MID(SUBSTITUTE(SUBSTITUTE($E23,";","；"),"；",REPT(" ",100)),901,100)),"") | P23: =IF(AND(配置数据库!$C26="售前填写",INDEX(配置数据库!$G26:$AG26,1,MATCH($B$3,配置数据库!$G$8:$AG$8,0))<>""),SUMPRODUCT((配置数据库!$C$10:$C26="售前填写")*(INDEX(配置数据库!$G$10:$AG26,0,MATCH($B$3,配置数据库!$G$8:$AG$8,0))<>"")),"") | Q23: =IF(AND(配置数据库!$C26="默认配置",INDEX(配置数据库!$G26:$AG26,1,MATCH($B$3,配置数据库!$G$8:$AG$8,0))<>""),SUMPRODUCT((配置数据库!$C$10:$C26="默认配置")*(INDEX(配置数据库!$G$10:$AG26,0,MATCH($B$3,配置数据库!$G$8:$AG$8,0))<>"")),"")
A24: =IFERROR(INDEX(配置数据库!$A:$A,MATCH(15,$P:$P,0)),"") -> 上视二维码相机 | B24: =IF($A24="","",IFERROR(LEFT(SUBSTITUTE(IFERROR(INDEX(配置数据库!$G:$AG,MATCH(15,$P:$P,0),MATCH($B$3,配置数据库!$G$8:$AG$8,0)),""),";","；"),FIND("；",SUBSTITUTE(IFERROR(INDEX(配置数据库!$G:$AG,MATCH(15,$P:$P,0),MATCH($B$3,配置数据库!$G$8:$AG$8,0)),""),";","；"))-1),IFERROR(INDEX(配置数据库!$G:$AG,MATCH(15,$P:$P,0),MATCH($B$3,配置数据库!$G$8:$AG$8,0)),""))) | C24: =IF($A24="","","售前填写") -> 售前填写 | D24: =IF($A24="","",IFERROR(INDEX(配置数据库!$B:$B,MATCH(15,$P:$P,0)),"")) | E24: =IF($A24="","",IFERROR(INDEX(配置数据库!$G:$AG,MATCH($A24,配置数据库!$A:$A,0),MATCH($B$3,配置数据库!$G$8:$AG$8,0)),"")) | F24: =IF(ISNUMBER(SEARCH("；",SUBSTITUTE($E24,";","；"))),TRIM(MID(SUBSTITUTE(SUBSTITUTE($E24,";","；"),"；",REPT(" ",100)),1,100)),"") | G24: =IF(ISNUMBER(SEARCH("；",SUBSTITUTE($E24,";","；"))),TRIM(MID(SUBSTITUTE(SUBSTITUTE($E24,";","；"),"；",REPT(" ",100)),101,100)),"") | H24: =IF(ISNUMBER(SEARCH("；",SUBSTITUTE($E24,";","；"))),TRIM(MID(SUBSTITUTE(SUBSTITUTE($E24,";","；"),"；",REPT(" ",100)),201,100)),"") | I24: =IF(ISNUMBER(SEARCH("；",SUBSTITUTE($E24,";","；"))),TRIM(MID(SUBSTITUTE(SUBSTITUTE($E24,";","；"),"；",REPT(" ",100)),301,100)),"") | J24: =IF(ISNUMBER(SEARCH("；",SUBSTITUTE($E24,";","；"))),TRIM(MID(SUBSTITUTE(SUBSTITUTE($E24,";","；"),"；",REPT(" ",100)),401,100)),"") | K24: =IF(ISNUMBER(SEARCH("；",SUBSTITUTE($E24,";","；"))),TRIM(MID(SUBSTITUTE(SUBSTITUTE($E24,";","；"),"；",REPT(" ",100)),501,100)),"") | L24: =IF(ISNUMBER(SEARCH("；",SUBSTITUTE($E24,";","；"))),TRIM(MID(SUBSTITUTE(SUBSTITUTE($E24,";","；"),"；",REPT(" ",100)),601,100)),"") | M24: =IF(ISNUMBER(SEARCH("；",SUBSTITUTE($E24,";","；"))),TRIM(MID(SUBSTITUTE(SUBSTITUTE($E24,";","；"),"；",REPT(" ",100)),701,100)),"") | N24: =IF(ISNUMBER(SEARCH("；",SUBSTITUTE($E24,";","；"))),TRIM(MID(SUBSTITUTE(SUBSTITUTE($E24,";","；"),"；",REPT(" ",100)),801,100)),"") | O24: =IF(ISNUMBER(SEARCH("；",SUBSTITUTE($E24,";","；"))),TRIM(MID(SUBSTITUTE(SUBSTITUTE($E24,";","；"),"；",REPT(" ",100)),901,100)),"") | P24: =IF(AND(配置数据库!$C28="售前填写",INDEX(配置数据库!$G28:$AG28,1,MATCH($B$3,配置数据库!$G$8:$AG$8,0))<>""),SUMPRODUCT((配置数据库!$C$10:$C28="售前填写")*(INDEX(配置数据库!$G$10:$AG28,0,MATCH($B$3,配置数据库!$G$8:$AG$8,0))<>"")),"") | Q24: =IF(AND(配置数据库!$C28="默认配置",INDEX(配置数据库!$G28:$AG28,1,MATCH($B$3,配置数据库!$G$8:$AG$8,0))<>""),SUMPRODUCT((配置数据库!$C$10:$C28="默认配置")*(INDEX(配置数据库!$G$10:$AG28,0,MATCH($B$3,配置数据库!$G$8:$AG$8,0))<>"")),"")
A25: =IFERROR(INDEX(配置数据库!$A:$A,MATCH(16,$P:$P,0)),"") | B25: =IF($A25="","",IFERROR(LEFT(SUBSTITUTE(IFERROR(INDEX(配置数据库!$G:$AG,MATCH(16,$P:$P,0),MATCH($B$3,配置数据库!$G$8:$AG$8,0)),""),";","；"),FIND("；",SUBSTITUTE(IFERROR(INDEX(配置数据库!$G:$AG,MATCH(16,$P:$P,0),MATCH($B$3,配置数据库!$G$8:$AG$8,0)),""),";","；"))-1),IFERROR(INDEX(配置数据库!$G:$AG,MATCH(16,$P:$P,0),MATCH($B$3,配置数据库!$G$8:$AG$8,0)),""))) | C25: =IF($A25="","","售前填写") | D25: =IF($A25="","",IFERROR(INDEX(配置数据库!$B:$B,MATCH(16,$P:$P,0)),"")) | E25: =IF($A25="","",IFERROR(INDEX(配置数据库!$G:$AG,MATCH($A25,配置数据库!$A:$A,0),MATCH($B$3,配置数据库!$G$8:$AG$8,0)),"")) | F25: =IF(ISNUMBER(SEARCH("；",SUBSTITUTE($E25,";","；"))),TRIM(MID(SUBSTITUTE(SUBSTITUTE($E25,";","；"),"；",REPT(" ",100)),1,100)),"") | G25: =IF(ISNUMBER(SEARCH("；",SUBSTITUTE($E25,";","；"))),TRIM(MID(SUBSTITUTE(SUBSTITUTE($E25,";","；"),"；",REPT(" ",100)),101,100)),"") | H25: =IF(ISNUMBER(SEARCH("；",SUBSTITUTE($E25,";","；"))),TRIM(MID(SUBSTITUTE(SUBSTITUTE($E25,";","；"),"；",REPT(" ",100)),201,100)),"") | I25: =IF(ISNUMBER(SEARCH("；",SUBSTITUTE($E25,";","；"))),TRIM(MID(SUBSTITUTE(SUBSTITUTE($E25,";","；"),"；",REPT(" ",100)),301,100)),"") | J25: =IF(ISNUMBER(SEARCH("；",SUBSTITUTE($E25,";","；"))),TRIM(MID(SUBSTITUTE(SUBSTITUTE($E25,";","；"),"；",REPT(" ",100)),401,100)),"") | K25: =IF(ISNUMBER(SEARCH("；",SUBSTITUTE($E25,";","；"))),TRIM(MID(SUBSTITUTE(SUBSTITUTE($E25,";","；"),"；",REPT(" ",100)),501,100)),"") | L25: =IF(ISNUMBER(SEARCH("；",SUBSTITUTE($E25,";","；"))),TRIM(MID(SUBSTITUTE(SUBSTITUTE($E25,";","；"),"；",REPT(" ",100)),601,100)),"") | M25: =IF(ISNUMBER(SEARCH("；",SUBSTITUTE($E25,";","；"))),TRIM(MID(SUBSTITUTE(SUBSTITUTE($E25,";","；"),"；",REPT(" ",100)),701,100)),"") | N25: =IF(ISNUMBER(SEARCH("；",SUBSTITUTE($E25,";","；"))),TRIM(MID(SUBSTITUTE(SUBSTITUTE($E25,";","；"),"；",REPT(" ",100)),801,100)),"") | O25: =IF(ISNUMBER(SEARCH("；",SUBSTITUTE($E25,";","；"))),TRIM(MID(SUBSTITUTE(SUBSTITUTE($E25,";","；"),"；",REPT(" ",100)),901,100)),"") | P25: =IF(AND(配置数据库!#REF!="售前填写",INDEX(配置数据库!#REF!,1,MATCH($B$3,配置数据库!$G$8:$AG$8,0))<>""),SUMPRODUCT((配置数据库!$C$10:$C28="售前填写")*(INDEX(配置数据库!$G$10:$AG28,0,MATCH($B$3,配置数据库!$G$8:$AG$8,0))<>"")),"") -> #REF! | Q25: =IF(AND(配置数据库!#REF!="默认配置",INDEX(配置数据库!#REF!,1,MATCH($B$3,配置数据库!$G$8:$AG$8,0))<>""),SUMPRODUCT((配置数据库!$C$10:$C28="默认配置")*(INDEX(配置数据库!$G$10:$AG28,0,MATCH($B$3,配置数据库!$G$8:$AG$8,0))<>"")),"") -> #REF!
A26: =IFERROR(INDEX(配置数据库!$A:$A,MATCH(17,$P:$P,0)),"") | B26: =IF($A26="","",IFERROR(LEFT(SUBSTITUTE(IFERROR(INDEX(配置数据库!$G:$AG,MATCH(17,$P:$P,0),MATCH($B$3,配置数据库!$G$8:$AG$8,0)),""),";","；"),FIND("；",SUBSTITUTE(IFERROR(INDEX(配置数据库!$G:$AG,MATCH(17,$P:$P,0),MATCH($B$3,配置数据库!$G$8:$AG$8,0)),""),";","；"))-1),IFERROR(INDEX(配置数据库!$G:$AG,MATCH(17,$P:$P,0),MATCH($B$3,配置数据库!$G$8:$AG$8,0)),""))) | C26: =IF($A26="","","售前填写") | D26: =IF($A26="","",IFERROR(INDEX(配置数据库!$B:$B,MATCH(17,$P:$P,0)),"")) | E26: =IF($A26="","",IFERROR(INDEX(配置数据库!$G:$AG,MATCH($A26,配置数据库!$A:$A,0),MATCH($B$3,配置数据库!$G$8:$AG$8,0)),"")) | F26: =IF(ISNUMBER(SEARCH("；",SUBSTITUTE($E26,";","；"))),TRIM(MID(SUBSTITUTE(SUBSTITUTE($E26,";","；"),"；",REPT(" ",100)),1,100)),"") | G26: =IF(ISNUMBER(SEARCH("；",SUBSTITUTE($E26,";","；"))),TRIM(MID(SUBSTITUTE(SUBSTITUTE($E26,";","；"),"；",REPT(" ",100)),101,100)),"") | H26: =IF(ISNUMBER(SEARCH("；",SUBSTITUTE($E26,";","；"))),TRIM(MID(SUBSTITUTE(SUBSTITUTE($E26,";","；"),"；",REPT(" ",100)),201,100)),"") | I26: =IF(ISNUMBER(SEARCH("；",SUBSTITUTE($E26,";","；"))),TRIM(MID(SUBSTITUTE(SUBSTITUTE($E26,";","；"),"；",REPT(" ",100)),301,100)),"") | J26: =IF(ISNUMBER(SEARCH("；",SUBSTITUTE($E26,";","；"))),TRIM(MID(SUBSTITUTE(SUBSTITUTE($E26,";","；"),"；",REPT(" ",100)),401,100)),"") | K26: =IF(ISNUMBER(SEARCH("；",SUBSTITUTE($E26,";","；"))),TRIM(MID(SUBSTITUTE(SUBSTITUTE($E26,";","；"),"；",REPT(" ",100)),501,100)),"") | L26: =IF(ISNUMBER(SEARCH("；",SUBSTITUTE($E26,";","；"))),TRIM(MID(SUBSTITUTE(SUBSTITUTE($E26,";","；"),"；",REPT(" ",100)),601,100)),"") | M26: =IF(ISNUMBER(SEARCH("；",SUBSTITUTE($E26,";","；"))),TRIM(MID(SUBSTITUTE(SUBSTITUTE($E26,";","；"),"；",REPT(" ",100)),701,100)),"") | N26: =IF(ISNUMBER(SEARCH("；",SUBSTITUTE($E26,";","；"))),TRIM(MID(SUBSTITUTE(SUBSTITUTE($E26,";","；"),"；",REPT(" ",100)),801,100)),"") | O26: =IF(ISNUMBER(SEARCH("；",SUBSTITUTE($E26,";","；"))),TRIM(MID(SUBSTITUTE(SUBSTITUTE($E26,";","；"),"；",REPT(" ",100)),901,100)),"") | P26: =IF(AND(配置数据库!$C34="售前填写",INDEX(配置数据库!$G34:$AG34,1,MATCH($B$3,配置数据库!$G$8:$AG$8,0))<>""),SUMPRODUCT((配置数据库!$C$10:$C34="售前填写")*(INDEX(配置数据库!$G$10:$AG34,0,MATCH($B$3,配置数据库!$G$8:$AG$8,0))<>"")),"") | Q26: =IF(AND(配置数据库!$C34="默认配置",INDEX(配置数据库!$G34:$AG34,1,MATCH($B$3,配置数据库!$G$8:$AG$8,0))<>""),SUMPRODUCT((配置数据库!$C$10:$C34="默认配置")*(INDEX(配置数据库!$G$10:$AG34,0,MATCH($B$3,配置数据库!$G$8:$AG$8,0))<>"")),"")
A27: =IFERROR(INDEX(配置数据库!$A:$A,MATCH(18,$P:$P,0)),"") | B27: =IF($A27="","",IFERROR(LEFT(SUBSTITUTE(IFERROR(INDEX(配置数据库!$G:$AG,MATCH(18,$P:$P,0),MATCH($B$3,配置数据库!$G$8:$AG$8,0)),""),";","；"),FIND("；",SUBSTITUTE(IFERROR(INDEX(配置数据库!$G:$AG,MATCH(18,$P:$P,0),MATCH($B$3,配置数据库!$G$8:$AG$8,0)),""),";","；"))-1),IFERROR(INDEX(配置数据库!$G:$AG,MATCH(18,$P:$P,0),MATCH($B$3,配置数据库!$G$8:$AG$8,0)),""))) | C27: =IF($A27="","","售前填写") | D27: =IF($A27="","",IFERROR(INDEX(配置数据库!$B:$B,MATCH(18,$P:$P,0)),"")) | E27: =IF($A27="","",IFERROR(INDEX(配置数据库!$G:$AG,MATCH($A27,配置数据库!$A:$A,0),MATCH($B$3,配置数据库!$G$8:$AG$8,0)),"")) | F27: =IF(ISNUMBER(SEARCH("；",SUBSTITUTE($E27,";","；"))),TRIM(MID(SUBSTITUTE(SUBSTITUTE($E27,";","；"),"；",REPT(" ",100)),1,100)),"") | G27: =IF(ISNUMBER(SEARCH("；",SUBSTITUTE($E27,";","；"))),TRIM(MID(SUBSTITUTE(SUBSTITUTE($E27,";","；"),"；",REPT(" ",100)),101,100)),"") | H27: =IF(ISNUMBER(SEARCH("；",SUBSTITUTE($E27,";","；"))),TRIM(MID(SUBSTITUTE(SUBSTITUTE($E27,";","；"),"；",REPT(" ",100)),201,100)),"") | I27: =IF(ISNUMBER(SEARCH("；",SUBSTITUTE($E27,";","；"))),TRIM(MID(SUBSTITUTE(SUBSTITUTE($E27,";","；"),"；",REPT(" ",100)),301,100)),"") | J27: =IF(ISNUMBER(SEARCH("；",SUBSTITUTE($E27,";","；"))),TRIM(MID(SUBSTITUTE(SUBSTITUTE($E27,";","；"),"；",REPT(" ",100)),401,100)),"") | K27: =IF(ISNUMBER(SEARCH("；",SUBSTITUTE($E27,";","；"))),TRIM(MID(SUBSTITUTE(SUBSTITUTE($E27,";","；"),"；",REPT(" ",100)),501,100)),"") | L27: =IF(ISNUMBER(SEARCH("；",SUBSTITUTE($E27,";","；"))),TRIM(MID(SUBSTITUTE(SUBSTITUTE($E27,";","；"),"；",REPT(" ",100)),601,100)),"") | M27: =IF(ISNUMBER(SEARCH("；",SUBSTITUTE($E27,";","；"))),TRIM(MID(SUBSTITUTE(SUBSTITUTE($E27,";","；"),"；",REPT(" ",100)),701,100)),"") | N27: =IF(ISNUMBER(SEARCH("；",SUBSTITUTE($E27,";","；"))),TRIM(MID(SUBSTITUTE(SUBSTITUTE($E27,";","；"),"；",REPT(" ",100)),801,100)),"") | O27: =IF(ISNUMBER(SEARCH("；",SUBSTITUTE($E27,";","；"))),TRIM(MID(SUBSTITUTE(SUBSTITUTE($E27,";","；"),"；",REPT(" ",100)),901,100)),"") | P27: =IF(AND(配置数据库!$C35="售前填写",INDEX(配置数据库!$G35:$AG35,1,MATCH($B$3,配置数据库!$G$8:$AG$8,0))<>""),SUMPRODUCT((配置数据库!$C$10:$C35="售前填写")*(INDEX(配置数据库!$G$10:$AG35,0,MATCH($B$3,配置数据库!$G$8:$AG$8,0))<>"")),"") -> 8 | Q27: =IF(AND(配置数据库!$C35="默认配置",INDEX(配置数据库!$G35:$AG35,1,MATCH($B$3,配置数据库!$G$8:$AG$8,0))<>""),SUMPRODUCT((配置数据库!$C$10:$C35="默认配置")*(INDEX(配置数据库!$G$10:$AG35,0,MATCH($B$3,配置数据库!$G$8:$AG$8,0))<>"")),"")
A28: =IFERROR(INDEX(配置数据库!$A:$A,MATCH(19,$P:$P,0)),"") | B28: =IF($A28="","",IFERROR(LEFT(SUBSTITUTE(IFERROR(INDEX(配置数据库!$G:$AG,MATCH(19,$P:$P,0),MATCH($B$3,配置数据库!$G$8:$AG$8,0)),""),";","；"),FIND("；",SUBSTITUTE(IFERROR(INDEX(配置数据库!$G:$AG,MATCH(19,$P:$P,0),MATCH($B$3,配置数据库!$G$8:$AG$8,0)),""),";","；"))-1),IFERROR(INDEX(配置数据库!$G:$AG,MATCH(19,$P:$P,0),MATCH($B$3,配置数据库!$G$8:$AG$8,0)),""))) | C28: =IF($A28="","","售前填写") | D28: =IF($A28="","",IFERROR(INDEX(配置数据库!$B:$B,MATCH(19,$P:$P,0)),"")) | E28: =IF($A28="","",IFERROR(INDEX(配置数据库!$G:$AG,MATCH($A28,配置数据库!$A:$A,0),MATCH($B$3,配置数据库!$G$8:$AG$8,0)),"")) | F28: =IF(ISNUMBER(SEARCH("；",SUBSTITUTE($E28,";","；"))),TRIM(MID(SUBSTITUTE(SUBSTITUTE($E28,";","；"),"；",REPT(" ",100)),1,100)),"") | G28: =IF(ISNUMBER(SEARCH("；",SUBSTITUTE($E28,";","；"))),TRIM(MID(SUBSTITUTE(SUBSTITUTE($E28,";","；"),"；",REPT(" ",100)),101,100)),"") | H28: =IF(ISNUMBER(SEARCH("；",SUBSTITUTE($E28,";","；"))),TRIM(MID(SUBSTITUTE(SUBSTITUTE($E28,";","；"),"；",REPT(" ",100)),201,100)),"") | I28: =IF(ISNUMBER(SEARCH("；",SUBSTITUTE($E28,";","；"))),TRIM(MID(SUBSTITUTE(SUBSTITUTE($E28,";","；"),"；",REPT(" ",100)),301,100)),"") | J28: =IF(ISNUMBER(SEARCH("；",SUBSTITUTE($E28,";","；"))),TRIM(MID(SUBSTITUTE(SUBSTITUTE($E28,";","；"),"；",REPT(" ",100)),401,100)),"") | K28: =IF(ISNUMBER(SEARCH("；",SUBSTITUTE($E28,";","；"))),TRIM(MID(SUBSTITUTE(SUBSTITUTE($E28,";","；"),"；",REPT(" ",100)),501,100)),"") | L28: =IF(ISNUMBER(SEARCH("；",SUBSTITUTE($E28,";","；"))),TRIM(MID(SUBSTITUTE(SUBSTITUTE($E28,";","；"),"；",REPT(" ",100)),601,100)),"") | M28: =IF(ISNUMBER(SEARCH("；",SUBSTITUTE($E28,";","；"))),TRIM(MID(SUBSTITUTE(SUBSTITUTE($E28,";","；"),"；",REPT(" ",100)),701,100)),"") | N28: =IF(ISNUMBER(SEARCH("；",SUBSTITUTE($E28,";","；"))),TRIM(MID(SUBSTITUTE(SUBSTITUTE($E28,";","；"),"；",REPT(" ",100)),801,100)),"") | O28: =IF(ISNUMBER(SEARCH("；",SUBSTITUTE($E28,";","；"))),TRIM(MID(SUBSTITUTE(SUBSTITUTE($E28,";","；"),"；",REPT(" ",100)),901,100)),"") | P28: =IF(AND(配置数据库!#REF!="售前填写",INDEX(配置数据库!#REF!,1,MATCH($B$3,配置数据库!$G$8:$AG$8,0))<>""),SUMPRODUCT((配置数据库!$C$10:$C35="售前填写")*(INDEX(配置数据库!$G$10:$AG35,0,MATCH($B$3,配置数据库!$G$8:$AG$8,0))<>"")),"") -> #REF! | Q28: =IF(AND(配置数据库!#REF!="默认配置",INDEX(配置数据库!#REF!,1,MATCH($B$3,配置数据库!$G$8:$AG$8,0))<>""),SUMPRODUCT((配置数据库!$C$10:$C35="默认配置")*(INDEX(配置数据库!$G$10:$AG35,0,MATCH($B$3,配置数据库!$G$8:$AG$8,0))<>"")),"") -> #REF!
A29: =IFERROR(INDEX(配置数据库!$A:$A,MATCH(20,$P:$P,0)),"") | B29: =IF($A29="","",IFERROR(LEFT(SUBSTITUTE(IFERROR(INDEX(配置数据库!$G:$AG,MATCH(20,$P:$P,0),MATCH($B$3,配置数据库!$G$8:$AG$8,0)),""),";","；"),FIND("；",SUBSTITUTE(IFERROR(INDEX(配置数据库!$G:$AG,MATCH(20,$P:$P,0),MATCH($B$3,配置数据库!$G$8:$AG$8,0)),""),";","；"))-1),IFERROR(INDEX(配置数据库!$G:$AG,MATCH(20,$P:$P,0),MATCH($B$3,配置数据库!$G$8:$AG$8,0)),""))) | C29: =IF($A29="","","售前填写") | D29: =IF($A29="","",IFERROR(INDEX(配置数据库!$B:$B,MATCH(20,$P:$P,0)),"")) | E29: =IF($A29="","",IFERROR(INDEX(配置数据库!$G:$AG,MATCH($A29,配置数据库!$A:$A,0),MATCH($B$3,配置数据库!$G$8:$AG$8,0)),"")) | F29: =IF(ISNUMBER(SEARCH("；",SUBSTITUTE($E29,";","；"))),TRIM(MID(SUBSTITUTE(SUBSTITUTE($E29,";","；"),"；",REPT(" ",100)),1,100)),"") | G29: =IF(ISNUMBER(SEARCH("；",SUBSTITUTE($E29,";","；"))),TRIM(MID(SUBSTITUTE(SUBSTITUTE($E29,";","；"),"；",REPT(" ",100)),101,100)),"") | H29: =IF(ISNUMBER(SEARCH("；",SUBSTITUTE($E29,";","；"))),TRIM(MID(SUBSTITUTE(SUBSTITUTE($E29,";","；"),"；",REPT(" ",100)),201,100)),"") | I29: =IF(ISNUMBER(SEARCH("；",SUBSTITUTE($E29,";","；"))),TRIM(MID(SUBSTITUTE(SUBSTITUTE($E29,";","；"),"；",REPT(" ",100)),301,100)),"") | J29: =IF(ISNUMBER(SEARCH("；",SUBSTITUTE($E29,";","；"))),TRIM(MID(SUBSTITUTE(SUBSTITUTE($E29,";","；"),"；",REPT(" ",100)),401,100)),"") | K29: =IF(ISNUMBER(SEARCH("；",SUBSTITUTE($E29,";","；"))),TRIM(MID(SUBSTITUTE(SUBSTITUTE($E29,";","；"),"；",REPT(" ",100)),501,100)),"") | L29: =IF(ISNUMBER(SEARCH("；",SUBSTITUTE($E29,";","；"))),TRIM(MID(SUBSTITUTE(SUBSTITUTE($E29,";","；"),"；",REPT(" ",100)),601,100)),"") | M29: =IF(ISNUMBER(SEARCH("；",SUBSTITUTE($E29,";","；"))),TRIM(MID(SUBSTITUTE(SUBSTITUTE($E29,";","；"),"；",REPT(" ",100)),701,100)),"") | N29: =IF(ISNUMBER(SEARCH("；",SUBSTITUTE($E29,";","；"))),TRIM(MID(SUBSTITUTE(SUBSTITUTE($E29,";","；"),"；",REPT(" ",100)),801,100)),"") | O29: =IF(ISNUMBER(SEARCH("；",SUBSTITUTE($E29,";","；"))),TRIM(MID(SUBSTITUTE(SUBSTITUTE($E29,";","；"),"；",REPT(" ",100)),901,100)),"") | P29: =IF(AND(配置数据库!$C39="售前填写",INDEX(配置数据库!$G39:$AG39,1,MATCH($B$3,配置数据库!$G$8:$AG$8,0))<>""),SUMPRODUCT((配置数据库!$C$10:$C39="售前填写")*(INDEX(配置数据库!$G$10:$AG39,0,MATCH($B$3,配置数据库!$G$8:$AG$8,0))<>"")),"") -> 10 | Q29: =IF(AND(配置数据库!$C39="默认配置",INDEX(配置数据库!$G39:$AG39,1,MATCH($B$3,配置数据库!$G$8:$AG$8,0))<>""),SUMPRODUCT((配置数据库!$C$10:$C39="默认配置")*(INDEX(配置数据库!$G$10:$AG39,0,MATCH($B$3,配置数据库!$G$8:$AG$8,0))<>"")),"")
A30: =IFERROR(INDEX(配置数据库!$A:$A,MATCH(21,$P:$P,0)),"") | B30: =IF($A30="","",IFERROR(LEFT(SUBSTITUTE(IFERROR(INDEX(配置数据库!$G:$AG,MATCH(21,$P:$P,0),MATCH($B$3,配置数据库!$G$8:$AG$8,0)),""),";","；"),FIND("；",SUBSTITUTE(IFERROR(INDEX(配置数据库!$G:$AG,MATCH(21,$P:$P,0),MATCH($B$3,配置数据库!$G$8:$AG$8,0)),""),";","；"))-1),IFERROR(INDEX(配置数据库!$G:$AG,MATCH(21,$P:$P,0),MATCH($B$3,配置数据库!$G$8:$AG$8,0)),""))) | C30: =IF($A30="","","售前填写") | D30: =IF($A30="","",IFERROR(INDEX(配置数据库!$B:$B,MATCH(21,$P:$P,0)),"")) | E30: =IF($A30="","",IFERROR(INDEX(配置数据库!$G:$AG,MATCH($A30,配置数据库!$A:$A,0),MATCH($B$3,配置数据库!$G$8:$AG$8,0)),"")) | F30: =IF(ISNUMBER(SEARCH("；",SUBSTITUTE($E30,";","；"))),TRIM(MID(SUBSTITUTE(SUBSTITUTE($E30,";","；"),"；",REPT(" ",100)),1,100)),"") | G30: =IF(ISNUMBER(SEARCH("；",SUBSTITUTE($E30,";","；"))),TRIM(MID(SUBSTITUTE(SUBSTITUTE($E30,";","；"),"；",REPT(" ",100)),101,100)),"") | H30: =IF(ISNUMBER(SEARCH("；",SUBSTITUTE($E30,";","；"))),TRIM(MID(SUBSTITUTE(SUBSTITUTE($E30,";","；"),"；",REPT(" ",100)),201,100)),"") | I30: =IF(ISNUMBER(SEARCH("；",SUBSTITUTE($E30,";","；"))),TRIM(MID(SUBSTITUTE(SUBSTITUTE($E30,";","；"),"；",REPT(" ",100)),301,100)),"") | J30: =IF(ISNUMBER(SEARCH("；",SUBSTITUTE($E30,";","；"))),TRIM(MID(SUBSTITUTE(SUBSTITUTE($E30,";","；"),"；",REPT(" ",100)),401,100)),"") | K30: =IF(ISNUMBER(SEARCH("；",SUBSTITUTE($E30,";","；"))),TRIM(MID(SUBSTITUTE(SUBSTITUTE($E30,";","；"),"；",REPT(" ",100)),501,100)),"") | L30: =IF(ISNUMBER(SEARCH("；",SUBSTITUTE($E30,";","；"))),TRIM(MID(SUBSTITUTE(SUBSTITUTE($E30,";","；"),"；",REPT(" ",100)),601,100)),"") | M30: =IF(ISNUMBER(SEARCH("；",SUBSTITUTE($E30,";","；"))),TRIM(MID(SUBSTITUTE(SUBSTITUTE($E30,";","；"),"；",REPT(" ",100)),701,100)),"") | N30: =IF(ISNUMBER(SEARCH("；",SUBSTITUTE($E30,";","；"))),TRIM(MID(SUBSTITUTE(SUBSTITUTE($E30,";","；"),"；",REPT(" ",100)),801,100)),"") | O30: =IF(ISNUMBER(SEARCH("；",SUBSTITUTE($E30,";","；"))),TRIM(MID(SUBSTITUTE(SUBSTITUTE($E30,";","；"),"；",REPT(" ",100)),901,100)),"") | P30: =IF(AND(配置数据库!$C41="售前填写",INDEX(配置数据库!$G41:$AG41,1,MATCH($B$3,配置数据库!$G$8:$AG$8,0))<>""),SUMPRODUCT((配置数据库!$C$10:$C41="售前填写")*(INDEX(配置数据库!$G$10:$AG41,0,MATCH($B$3,配置数据库!$G$8:$AG$8,0))<>"")),"") | Q30: =IF(AND(配置数据库!$C41="默认配置",INDEX(配置数据库!$G41:$AG41,1,MATCH($B$3,配置数据库!$G$8:$AG$8,0))<>""),SUMPRODUCT((配置数据库!$C$10:$C41="默认配置")*(INDEX(配置数据库!$G$10:$AG41,0,MATCH($B$3,配置数据库!$G$8:$AG$8,0))<>"")),"")
A31: =IFERROR(INDEX(配置数据库!$A:$A,MATCH(22,$P:$P,0)),"") | B31: =IF($A31="","",IFERROR(LEFT(SUBSTITUTE(IFERROR(INDEX(配置数据库!$G:$AG,MATCH(22,$P:$P,0),MATCH($B$3,配置数据库!$G$8:$AG$8,0)),""),";","；"),FIND("；",SUBSTITUTE(IFERROR(INDEX(配置数据库!$G:$AG,MATCH(22,$P:$P,0),MATCH($B$3,配置数据库!$G$8:$AG$8,0)),""),";","；"))-1),IFERROR(INDEX(配置数据库!$G:$AG,MATCH(22,$P:$P,0),MATCH($B$3,配置数据库!$G$8:$AG$8,0)),""))) | C31: =IF($A31="","","售前填写") | D31: =IF($A31="","",IFERROR(INDEX(配置数据库!$B:$B,MATCH(22,$P:$P,0)),"")) | E31: =IF($A31="","",IFERROR(INDEX(配置数据库!$G:$AG,MATCH($A31,配置数据库!$A:$A,0),MATCH($B$3,配置数据库!$G$8:$AG$8,0)),"")) | F31: =IF(ISNUMBER(SEARCH("；",SUBSTITUTE($E31,";","；"))),TRIM(MID(SUBSTITUTE(SUBSTITUTE($E31,";","；"),"；",REPT(" ",100)),1,100)),"") | G31: =IF(ISNUMBER(SEARCH("；",SUBSTITUTE($E31,";","；"))),TRIM(MID(SUBSTITUTE(SUBSTITUTE($E31,";","；"),"；",REPT(" ",100)),101,100)),"") | H31: =IF(ISNUMBER(SEARCH("；",SUBSTITUTE($E31,";","；"))),TRIM(MID(SUBSTITUTE(SUBSTITUTE($E31,";","；"),"；",REPT(" ",100)),201,100)),"") | I31: =IF(ISNUMBER(SEARCH("；",SUBSTITUTE($E31,";","；"))),TRIM(MID(SUBSTITUTE(SUBSTITUTE($E31,";","；"),"；",REPT(" ",100)),301,100)),"") | J31: =IF(ISNUMBER(SEARCH("；",SUBSTITUTE($E31,";","；"))),TRIM(MID(SUBSTITUTE(SUBSTITUTE($E31,";","；"),"；",REPT(" ",100)),401,100)),"") | K31: =IF(ISNUMBER(SEARCH("；",SUBSTITUTE($E31,";","；"))),TRIM(MID(SUBSTITUTE(SUBSTITUTE($E31,";","；"),"；",REPT(" ",100)),501,100)),"") | L31: =IF(ISNUMBER(SEARCH("；",SUBSTITUTE($E31,";","；"))),TRIM(MID(SUBSTITUTE(SUBSTITUTE($E31,";","；"),"；",REPT(" ",100)),601,100)),"") | M31: =IF(ISNUMBER(SEARCH("；",SUBSTITUTE($E31,";","；"))),TRIM(MID(SUBSTITUTE(SUBSTITUTE($E31,";","；"),"；",REPT(" ",100)),701,100)),"") | N31: =IF(ISNUMBER(SEARCH("；",SUBSTITUTE($E31,";","；"))),TRIM(MID(SUBSTITUTE(SUBSTITUTE($E31,";","；"),"；",REPT(" ",100)),801,100)),"") | O31: =IF(ISNUMBER(SEARCH("；",SUBSTITUTE($E31,";","；"))),TRIM(MID(SUBSTITUTE(SUBSTITUTE($E31,";","；"),"；",REPT(" ",100)),901,100)),"") | P31: =IF(AND(配置数据库!$C42="售前填写",INDEX(配置数据库!$G42:$AG42,1,MATCH($B$3,配置数据库!$G$8:$AG$8,0))<>""),SUMPRODUCT((配置数据库!$C$10:$C42="售前填写")*(INDEX(配置数据库!$G$10:$AG42,0,MATCH($B$3,配置数据库!$G$8:$AG$8,0))<>"")),"") | Q31: =IF(AND(配置数据库!$C42="默认配置",INDEX(配置数据库!$G42:$AG42,1,MATCH($B$3,配置数据库!$G$8:$AG$8,0))<>""),SUMPRODUCT((配置数据库!$C$10:$C42="默认配置")*(INDEX(配置数据库!$G$10:$AG42,0,MATCH($B$3,配置数据库!$G$8:$AG$8,0))<>"")),"")
A32: =IFERROR(INDEX(配置数据库!$A:$A,MATCH(23,$P:$P,0)),"") | B32: =IF($A32="","",IFERROR(LEFT(SUBSTITUTE(IFERROR(INDEX(配置数据库!$G:$AG,MATCH(23,$P:$P,0),MATCH($B$3,配置数据库!$G$8:$AG$8,0)),""),";","；"),FIND("；",SUBSTITUTE(IFERROR(INDEX(配置数据库!$G:$AG,MATCH(23,$P:$P,0),MATCH($B$3,配置数据库!$G$8:$AG$8,0)),""),";","；"))-1),IFERROR(INDEX(配置数据库!$G:$AG,MATCH(23,$P:$P,0),MATCH($B$3,配置数据库!$G$8:$AG$8,0)),""))) | C32: =IF($A32="","","售前填写") | D32: =IF($A32="","",IFERROR(INDEX(配置数据库!$B:$B,MATCH(23,$P:$P,0)),"")) | E32: =IF($A32="","",IFERROR(INDEX(配置数据库!$G:$AG,MATCH($A32,配置数据库!$A:$A,0),MATCH($B$3,配置数据库!$G$8:$AG$8,0)),"")) | F32: =IF(ISNUMBER(SEARCH("；",SUBSTITUTE($E32,";","；"))),TRIM(MID(SUBSTITUTE(SUBSTITUTE($E32,";","；"),"；",REPT(" ",100)),1,100)),"") | G32: =IF(ISNUMBER(SEARCH("；",SUBSTITUTE($E32,";","；"))),TRIM(MID(SUBSTITUTE(SUBSTITUTE($E32,";","；"),"；",REPT(" ",100)),101,100)),"") | H32: =IF(ISNUMBER(SEARCH("；",SUBSTITUTE($E32,";","；"))),TRIM(MID(SUBSTITUTE(SUBSTITUTE($E32,";","；"),"；",REPT(" ",100)),201,100)),"") | I32: =IF(ISNUMBER(SEARCH("；",SUBSTITUTE($E32,";","；"))),TRIM(MID(SUBSTITUTE(SUBSTITUTE($E32,";","；"),"；",REPT(" ",100)),301,100)),"") | J32: =IF(ISNUMBER(SEARCH("；",SUBSTITUTE($E32,";","；"))),TRIM(MID(SUBSTITUTE(SUBSTITUTE($E32,";","；"),"；",REPT(" ",100)),401,100)),"") | K32: =IF(ISNUMBER(SEARCH("；",SUBSTITUTE($E32,";","；"))),TRIM(MID(SUBSTITUTE(SUBSTITUTE($E32,";","；"),"；",REPT(" ",100)),501,100)),"") | L32: =IF(ISNUMBER(SEARCH("；",SUBSTITUTE($E32,";","；"))),TRIM(MID(SUBSTITUTE(SUBSTITUTE($E32,";","；"),"；",REPT(" ",100)),601,100)),"") | M32: =IF(ISNUMBER(SEARCH("；",SUBSTITUTE($E32,";","；"))),TRIM(MID(SUBSTITUTE(SUBSTITUTE($E32,";","；"),"；",REPT(" ",100)),701,100)),"") | N32: =IF(ISNUMBER(SEARCH("；",SUBSTITUTE($E32,";","；"))),TRIM(MID(SUBSTITUTE(SUBSTITUTE($E32,";","；"),"；",REPT(" ",100)),801,100)),"") | O32: =IF(ISNUMBER(SEARCH("；",SUBSTITUTE($E32,";","；"))),TRIM(MID(SUBSTITUTE(SUBSTITUTE($E32,";","；"),"；",REPT(" ",100)),901,100)),"") | P32: =IF(AND(配置数据库!$C46="售前填写",INDEX(配置数据库!$G46:$AG46,1,MATCH($B$3,配置数据库!$G$8:$AG$8,0))<>""),SUMPRODUCT((配置数据库!$C$10:$C46="售前填写")*(INDEX(配置数据库!$G$10:$AG46,0,MATCH($B$3,配置数据库!$G$8:$AG$8,0))<>"")),"") | Q32: =IF(AND(配置数据库!$C46="默认配置",INDEX(配置数据库!$G46:$AG46,1,MATCH($B$3,配置数据库!$G$8:$AG$8,0))<>""),SUMPRODUCT((配置数据库!$C$10:$C46="默认配置")*(INDEX(配置数据库!$G$10:$AG46,0,MATCH($B$3,配置数据库!$G$8:$AG$8,0))<>"")),"")
A33: =IFERROR(INDEX(配置数据库!$A:$A,MATCH(24,$P:$P,0)),"") | B33: =IF($A33="","",IFERROR(LEFT(SUBSTITUTE(IFERROR(INDEX(配置数据库!$G:$AG,MATCH(24,$P:$P,0),MATCH($B$3,配置数据库!$G$8:$AG$8,0)),""),";","；"),FIND("；",SUBSTITUTE(IFERROR(INDEX(配置数据库!$G:$AG,MATCH(24,$P:$P,0),MATCH($B$3,配置数据库!$G$8:$AG$8,0)),""),";","；"))-1),IFERROR(INDEX(配置数据库!$G:$AG,MATCH(24,$P:$P,0),MATCH($B$3,配置数据库!$G$8:$AG$8,0)),""))) | C33: =IF($A33="","","售前填写") | D33: =IF($A33="","",IFERROR(INDEX(配置数据库!$B:$B,MATCH(24,$P:$P,0)),"")) | E33: =IF($A33="","",IFERROR(INDEX(配置数据库!$G:$AG,MATCH($A33,配置数据库!$A:$A,0),MATCH($B$3,配置数据库!$G$8:$AG$8,0)),"")) | F33: =IF(ISNUMBER(SEARCH("；",SUBSTITUTE($E33,";","；"))),TRIM(MID(SUBSTITUTE(SUBSTITUTE($E33,";","；"),"；",REPT(" ",100)),1,100)),"") | G33: =IF(ISNUMBER(SEARCH("；",SUBSTITUTE($E33,";","；"))),TRIM(MID(SUBSTITUTE(SUBSTITUTE($E33,";","；"),"；",REPT(" ",100)),101,100)),"") | H33: =IF(ISNUMBER(SEARCH("；",SUBSTITUTE($E33,";","；"))),TRIM(MID(SUBSTITUTE(SUBSTITUTE($E33,";","；"),"；",REPT(" ",100)),201,100)),"") | I33: =IF(ISNUMBER(SEARCH("；",SUBSTITUTE($E33,";","；"))),TRIM(MID(SUBSTITUTE(SUBSTITUTE($E33,";","；"),"；",REPT(" ",100)),301,100)),"") | J33: =IF(ISNUMBER(SEARCH("；",SUBSTITUTE($E33,";","；"))),TRIM(MID(SUBSTITUTE(SUBSTITUTE($E33,";","；"),"；",REPT(" ",100)),401,100)),"") | K33: =IF(ISNUMBER(SEARCH("；",SUBSTITUTE($E33,";","；"))),TRIM(MID(SUBSTITUTE(SUBSTITUTE($E33,";","；"),"；",REPT(" ",100)),501,100)),"") | L33: =IF(ISNUMBER(SEARCH("；",SUBSTITUTE($E33,";","；"))),TRIM(MID(SUBSTITUTE(SUBSTITUTE($E33,";","；"),"；",REPT(" ",100)),601,100)),"") | M33: =IF(ISNUMBER(SEARCH("；",SUBSTITUTE($E33,";","；"))),TRIM(MID(SUBSTITUTE(SUBSTITUTE($E33,";","；"),"；",REPT(" ",100)),701,100)),"") | N33: =IF(ISNUMBER(SEARCH("；",SUBSTITUTE($E33,";","；"))),TRIM(MID(SUBSTITUTE(SUBSTITUTE($E33,";","；"),"；",REPT(" ",100)),801,100)),"") | O33: =IF(ISNUMBER(SEARCH("；",SUBSTITUTE($E33,";","；"))),TRIM(MID(SUBSTITUTE(SUBSTITUTE($E33,";","；"),"；",REPT(" ",100)),901,100)),"") | P33: =IF(AND(配置数据库!$C47="售前填写",INDEX(配置数据库!$G47:$AG47,1,MATCH($B$3,配置数据库!$G$8:$AG$8,0))<>""),SUMPRODUCT((配置数据库!$C$10:$C47="售前填写")*(INDEX(配置数据库!$G$10:$AG47,0,MATCH($B$3,配置数据库!$G$8:$AG$8,0))<>"")),"") | Q33: =IF(AND(配置数据库!$C47="默认配置",INDEX(配置数据库!$G47:$AG47,1,MATCH($B$3,配置数据库!$G$8:$AG$8,0))<>""),SUMPRODUCT((配置数据库!$C$10:$C47="默认配置")*(INDEX(配置数据库!$G$10:$AG47,0,MATCH($B$3,配置数据库!$G$8:$AG$8,0))<>"")),"")
